Workbook

Sheet 사용법
B3: 사용법
B4: "배정"이라는 시트에 반과 이름을 써 넣으면 자동적으로 "해당면학실 층" 시트에 반영이 되어 편리하게 사용하실 수 있습니다. "면학실 2층"시트는 건드리지 말아주시기 바랍니다.

Sheet 자율관 배정
B2: 자리번호 | C2: HR | D2: 이름 | E2: 학번 | F2: 성별 | G2: 비고
B3: 2A001
B4: 2A003
B5: 2A005
B6: 2A007
B7: 2A009
B8: 2A011
B9: 2A013
B10: 2A015
B11: 2A017
B12: 2A019
B13: 2A021
B14: 2A023
... B183: 2D121

Sheet 자율관2층
B2: 자율관 2층 배치도
B6: 2B069 | C6: 2B068 | D6: 2B067 | E6: 2B066 | F6: 2B065 | H6: 2B064 | I6: 2B063 | J6: 2B062 | K6: 2B061 | L6: 2B060 | O6: 2B059 | P6: 2B058 | Q6: 2B057 | R6: 2B056 | S6: 2B055 | V6: 2C045 | W6: 2C044 | X6: 2C043 | Y6: 2C042 | Z6: 2C041 | AB6: 2C040 | AC6: 2C039 | AD6: 2C038 | AE6: 2C037 | AF6: 2C036
B7: =IFERROR(VLOOKUP(B6,'자율관 배정'!$B:$G,3,FALSE)&"("&VLOOKUP(B6,'자율관 배정'!$B:$F,2,FALSE)&")","") -> () | C7: =IFERROR(VLOOKUP(C6,'자율관 배정'!$B:$G,3,FALSE)&"("&VLOOKUP(C6,'자율관 배정'!$B:$F,2,FALSE)&")","") | D7: =IFERROR(VLOOKUP(D6,'자율관 배정'!$B:$G,3,FALSE)&"("&VLOOKUP(D6,'자율관 배정'!$B:$F,2,FALSE)&")","") -> () | E7: =IFERROR(VLOOKUP(E6,'자율관 배정'!$B:$G,3,FALSE)&"("&VLOOKUP(E6,'자율관 배정'!$B:$F,2,FALSE)&")","") | F7: =IFERROR(VLOOKUP(F6,'자율관 배정'!$B:$G,3,FALSE)&"("&VLOOKUP(F6,'자율관 배정'!$B:$F,2,FALSE)&")","") -> () | H7: =IFERROR(VLOOKUP(H6,'자율관 배정'!$B:$G,3,FALSE)&"("&VLOOKUP(H6,'자율관 배정'!$B:$F,2,FALSE)&")","") | I7: =IFERROR(VLOOKUP(I6,'자율관 배정'!$B:$G,3,FALSE)&"("&VLOOKUP(I6,'자율관 배정'!$B:$F,2,FALSE)&")","") -> () | J7: =IFERROR(VLOOKUP(J6,'자율관 배정'!$B:$G,3,FALSE)&"("&VLOOKUP(J6,'자율관 배정'!$B:$F,2,FALSE)&")","") | K7: =IFERROR(VLOOKUP(K6,'자율관 배정'!$B:$G,3,FALSE)&"("&VLOOKUP(K6,'자율관 배정'!$B:$F,2,FALSE)&")","") -> () | L7: =IFERROR(VLOOKUP(L6,'자율관 배정'!$B:$G,3,FALSE)&"("&VLOOKUP(L6,'자율관 배정'!$B:$F,2,FALSE)&")","") | O7: =IFERROR(VLOOKUP(O6,'자율관 배정'!$B:$G,3,FALSE)&"("&VLOOKUP(O6,'자율관 배정'!$B:$F,2,FALSE)&")","") -> () | P7: =IFERROR(VLOOKUP(P6,'자율관 배정'!$B:$G,3,FALSE)&"("&VLOOKUP(P6,'자율관 배정'!$B:$F,2,FALSE)&")","") | Q7: =IFERROR(VLOOKUP(Q6,'자율관 배정'!$B:$G,3,FALSE)&"("&VLOOKUP(Q6,'자율관 배정'!$B:$F,2,FALSE)&")","") -> () | R7: =IFERROR(VLOOKUP(R6,'자율관 배정'!$B:$G,3,FALSE)&"("&VLOOKUP(R6,'자율관 배정'!$B:$F,2,FALSE)&")","") | S7: =IFERROR(VLOOKUP(S6,'자율관 배정'!$B:$G,3,FALSE)&"("&VLOOKUP(S6,'자율관 배정'!$B:$F,2,FALSE)&")","") -> () | V7: =IFERROR(VLOOKUP(V6,'자율관 배정'!$B:$G,3,FALSE)&"("&VLOOKUP(V6,'자율관 배정'!$B:$F,2,FALSE)&")","") -> () | W7: =IFERROR(VLOOKUP(W6,'자율관 배정'!$B:$G,3,FALSE)&"("&VLOOKUP(W6,'자율관 배정'!$B:$F,2,FALSE)&")","") | X7: =IFERROR(VLOOKUP(X6,'자율관 배정'!$B:$G,3,FALSE)&"("&VLOOKUP(X6,'자율관 배정'!$B:$F,2,FALSE)&")","") -> () | Y7: =IFERROR(VLOOKUP(Y6,'자율관 배정'!$B:$G,3,FALSE)&"("&VLOOKUP(Y6,'자율관 배정'!$B:$F,2,FALSE)&")","") | Z7: =IFERROR(VLOOKUP(Z6,'자율관 배정'!$B:$G,3,FALSE)&"("&VLOOKUP(Z6,'자율관 배정'!$B:$F,2,FALSE)&")","") -> () | AB7: =IFERROR(VLOOKUP(AB6,'자율관 배정'!$B:$G,3,FALSE)&"("&VLOOKUP(AB6,'자율관 배정'!$B:$F,2,FALSE)&")","") | AC7: =IFERROR(VLOOKUP(AC6,'자율관 배정'!$B:$G,3,FALSE)&"("&VLOOKUP(AC6,'자율관 배정'!$B:$F,2,FALSE)&")","") -> () | AD7: =IFERROR(VLOOKUP(AD6,'자율관 배정'!$B:$G,3,FALSE)&"("&VLOOKUP(AD6,'자율관 배정'!$B:$F,2,FALSE)&")","") | AE7: =IFERROR(VLOOKUP(AE6,'자율관 배정'!$B:$G,3,FALSE)&"("&VLOOKUP(AE6,'자율관 배정'!$B:$F,2,FALSE)&")","") -> () | AF7: =IFERROR(VLOOKUP(AF6,'자율관 배정'!$B:$G,3,FALSE)&"("&VLOOKUP(AF6,'자율관 배정'!$B:$F,2,FALSE)&")","")
B8: 2B054 | C8: 2B053 | D8: 2B052 | E8: 2B051 | F8: 2B050 | H8: 2B049 | I8: 2B048 | J8: 2B047 | K8: 2B046 | L8: 2B045 | O8: 2B044 | P8: 2B043 | Q8: 2B042 | R8: 2B041 | S8: 2B040 | V8: 2C035 | W8: 2C034 | X8: 2C033 | Y8: 2C032 | Z8: 2C031 | AB8: 2C030 | AC8: 2C029 | AD8: 2C028 | AE8: 2C027 | AF8: 2C026
B9: =IFERROR(VLOOKUP(B8,'자율관 배정'!$B:$G,3,FALSE)&"("&VLOOKUP(B8,'자율관 배정'!$B:$F,2,FALSE)&")","") | C9: =IFERROR(VLOOKUP(C8,'자율관 배정'!$B:$G,3,FALSE)&"("&VLOOKUP(C8,'자율관 배정'!$B:$F,2,FALSE)&")","") -> () | D9: =IFERROR(VLOOKUP(D8,'자율관 배정'!$B:$G,3,FALSE)&"("&VLOOKUP(D8,'자율관 배정'!$B:$F,2,FALSE)&")","") | E9: =IFERROR(VLOOKUP(E8,'자율관 배정'!$B:$G,3,FALSE)&"("&VLOOKUP(E8,'자율관 배정'!$B:$F,2,FALSE)&")","") -> () | F9: =IFERROR(VLOOKUP(F8,'자율관 배정'!$B:$G,3,FALSE)&"("&VLOOKUP(F8,'자율관 배정'!$B:$F,2,FALSE)&")","") | H9: =IFERROR(VLOOKUP(H8,'자율관 배정'!$B:$G,3,FALSE)&"("&VLOOKUP(H8,'자율관 배정'!$B:$F,2,FALSE)&")","") -> () | I9: =IFERROR(VLOOKUP(I8,'자율관 배정'!$B:$G,3,FALSE)&"("&VLOOKUP(I8,'자율관 배정'!$B:$F,2,FALSE)&")","") | J9: =IFERROR(VLOOKUP(J8,'자율관 배정'!$B:$G,3,FALSE)&"("&VLOOKUP(J8,'자율관 배정'!$B:$F,2,FALSE)&")","") -> () | K9: =IFERROR(VLOOKUP(K8,'자율관 배정'!$B:$G,3,FALSE)&"("&VLOOKUP(K8,'자율관 배정'!$B:$F,2,FALSE)&")","") | L9: =IFERROR(VLOOKUP(L8,'자율관 배정'!$B:$G,3,FALSE)&"("&VLOOKUP(L8,'자율관 배정'!$B:$F,2,FALSE)&")","") -> () | O9: =IFERROR(VLOOKUP(O8,'자율관 배정'!$B:$G,3,FALSE)&"("&VLOOKUP(O8,'자율관 배정'!$B:$F,2,FALSE)&")","") | P9: =IFERROR(VLOOKUP(P8,'자율관 배정'!$B:$G,3,FALSE)&"("&VLOOKUP(P8,'자율관 배정'!$B:$F,2,FALSE)&")","") -> () | Q9: =IFERROR(VLOOKUP(Q8,'자율관 배정'!$B:$G,3,FALSE)&"("&VLOOKUP(Q8,'자율관 배정'!$B:$F,2,FALSE)&")","") | R9: =IFERROR(VLOOKUP(R8,'자율관 배정'!$B:$G,3,FALSE)&"("&VLOOKUP(R8,'자율관 배정'!$B:$F,2,FALSE)&")","") -> () | S9: =IFERROR(VLOOKUP(S8,'자율관 배정'!$B:$G,3,FALSE)&"("&VLOOKUP(S8,'자율관 배정'!$B:$F,2,FALSE)&")","") | V9: =IFERROR(VLOOKUP(V8,'자율관 배정'!$B:$G,3,FALSE)&"("&VLOOKUP(V8,'자율관 배정'!$B:$F,2,FALSE)&")","") | W9: =IFERROR(VLOOKUP(W8,'자율관 배정'!$B:$G,3,FALSE)&"("&VLOOKUP(W8,'자율관 배정'!$B:$F,2,FALSE)&")","") -> () | X9: =IFERROR(VLOOKUP(X8,'자율관 배정'!$B:$G,3,FALSE)&"("&VLOOKUP(X8,'자율관 배정'!$B:$F,2,FALSE)&")","") | Y9: =IFERROR(VLOOKUP(Y8,'자율관 배정'!$B:$G,3,FALSE)&"("&VLOOKUP(Y8,'자율관 배정'!$B:$F,2,FALSE)&")","") -> () | Z9: =IFERROR(VLOOKUP(Z8,'자율관 배정'!$B:$G,3,FALSE)&"("&VLOOKUP(Z8,'자율관 배정'!$B:$F,2,FALSE)&")","") | AB9: =IFERROR(VLOOKUP(AB8,'자율관 배정'!$B:$G,3,FALSE)&"("&VLOOKUP(AB8,'자율관 배정'!$B:$F,2,FALSE)&")","") -> () | AC9: =IFERROR(VLOOKUP(AC8,'자율관 배정'!$B:$G,3,FALSE)&"("&VLOOKUP(AC8,'자율관 배정'!$B:$F,2,FALSE)&")","") | AD9: =IFERROR(VLOOKUP(AD8,'자율관 배정'!$B:$G,3,FALSE)&"("&VLOOKUP(AD8,'자율관 배정'!$B:$F,2,FALSE)&")","") -> () | AE9: =IFERROR(VLOOKUP(AE8,'자율관 배정'!$B:$G,3,FALSE)&"("&VLOOKUP(AE8,'자율관 배정'!$B:$F,2,FALSE)&")","") | AF9: =IFERROR(VLOOKUP(AF8,'자율관 배정'!$B:$G,3,FALSE)&"("&VLOOKUP(AF8,'자율관 배정'!$B:$F,2,FALSE)&")","") -> ()
B11: 2B039 | C11: 2B038 | D11: 2B037 | E11: 2B036 | F11: 2B035 | H11: 2B034 | I11: 2B033 | J11: 2B032 | K11: 2B031 | L11: 2B030 | O11: 2B029 | P11: 2B28 | Q11: 2B027 | R11: 2B026 | S11: 2B025 | V11: 2C025 | W11: 2C024 | X11: 2C023 | Y11: 2C022 | Z11: 2C021 | AB11: 2C020 | AC11: 2C019 | AD11: 2C018 | AE11: 2C017 | AF11: 2C016
B12: =IFERROR(VLOOKUP(B11,'자율관 배정'!$B:$G,3,FALSE)&"("&VLOOKUP(B11,'자율관 배정'!$B:$F,2,FALSE)&")","") -> () | C12: =IFERROR(VLOOKUP(C11,'자율관 배정'!$B:$G,3,FALSE)&"("&VLOOKUP(C11,'자율관 배정'!$B:$F,2,FALSE)&")","") | D12: =IFERROR(VLOOKUP(D11,'자율관 배정'!$B:$G,3,FALSE)&"("&VLOOKUP(D11,'자율관 배정'!$B:$F,2,FALSE)&")","") -> () | E12: =IFERROR(VLOOKUP(E11,'자율관 배정'!$B:$G,3,FALSE)&"("&VLOOKUP(E11,'자율관 배정'!$B:$F,2,FALSE)&")","") | F12: =IFERROR(VLOOKUP(F11,'자율관 배정'!$B:$G,3,FALSE)&"("&VLOOKUP(F11,'자율관 배정'!$B:$F,2,FALSE)&")","") -> () | H12: =IFERROR(VLOOKUP(H11,'자율관 배정'!$B:$G,3,FALSE)&"("&VLOOKUP(H11,'자율관 배정'!$B:$F,2,FALSE)&")","") | I12: =IFERROR(VLOOKUP(I11,'자율관 배정'!$B:$G,3,FALSE)&"("&VLOOKUP(I11,'자율관 배정'!$B:$F,2,FALSE)&")","") -> () | J12: =IFERROR(VLOOKUP(J11,'자율관 배정'!$B:$G,3,FALSE)&"("&VLOOKUP(J11,'자율관 배정'!$B:$F,2,FALSE)&")","") | K12: =IFERROR(VLOOKUP(K11,'자율관 배정'!$B:$G,3,FALSE)&"("&VLOOKUP(K11,'자율관 배정'!$B:$F,2,FALSE)&")","") -> () | L12: =IFERROR(VLOOKUP(L11,'자율관 배정'!$B:$G,3,FALSE)&"("&VLOOKUP(L11,'자율관 배정'!$B:$F,2,FALSE)&")","") | O12: =IFERROR(VLOOKUP(O11,'자율관 배정'!$B:$G,3,FALSE)&"("&VLOOKUP(O11,'자율관 배정'!$B:$F,2,FALSE)&")","") -> () | P12: =IFERROR(VLOOKUP(P11,'자율관 배정'!$B:$G,3,FALSE)&"("&VLOOKUP(P11,'자율관 배정'!$B:$F,2,FALSE)&")","") | Q12: =IFERROR(VLOOKUP(Q11,'자율관 배정'!$B:$G,3,FALSE)&"("&VLOOKUP(Q11,'자율관 배정'!$B:$F,2,FALSE)&")","") -> () | R12: =IFERROR(VLOOKUP(R11,'자율관 배정'!$B:$G,3,FALSE)&"("&VLOOKUP(R11,'자율관 배정'!$B:$F,2,FALSE)&")","") | S12: =IFERROR(VLOOKUP(S11,'자율관 배정'!$B:$G,3,FALSE)&"("&VLOOKUP(S11,'자율관 배정'!$B:$F,2,FALSE)&")","") -> () | V12: =IFERROR(VLOOKUP(V11,'자율관 배정'!$B:$G,3,FALSE)&"("&VLOOKUP(V11,'자율관 배정'!$B:$F,2,FALSE)&")","") -> () | W12: =IFERROR(VLOOKUP(W11,'자율관 배정'!$B:$G,3,FALSE)&"("&VLOOKUP(W11,'자율관 배정'!$B:$F,2,FALSE)&")","") | X12: =IFERROR(VLOOKUP(X11,'자율관 배정'!$B:$G,3,FALSE)&"("&VLOOKUP(X11,'자율관 배정'!$B:$F,2,FALSE)&")","") -> () | Y12: =IFERROR(VLOOKUP(Y11,'자율관 배정'!$B:$G,3,FALSE)&"("&VLOOKUP(Y11,'자율관 배정'!$B:$F,2,FALSE)&")","") | Z12: =IFERROR(VLOOKUP(Z11,'자율관 배정'!$B:$G,3,FALSE)&"("&VLOOKUP(Z11,'자율관 배정'!$B:$F,2,FALSE)&")","") -> () | AB12: =IFERROR(VLOOKUP(AB11,'자율관 배정'!$B:$G,3,FALSE)&"("&VLOOKUP(AB11,'자율관 배정'!$B:$F,2,FALSE)&")","") | AC12: =IFERROR(VLOOKUP(AC11,'자율관 배정'!$B:$G,3,FALSE)&"("&VLOOKUP(AC11,'자율관 배정'!$B:$F,2,FALSE)&")","") -> () | AD12: =IFERROR(VLOOKUP(AD11,'자율관 배정'!$B:$G,3,FALSE)&"("&VLOOKUP(AD11,'자율관 배정'!$B:$F,2,FALSE)&")","") | AE12: =IFERROR(VLOOKUP(AE11,'자율관 배정'!$B:$G,3,FALSE)&"("&VLOOKUP(AE11,'자율관 배정'!$B:$F,2,FALSE)&")","") -> () | AF12: =IFERROR(VLOOKUP(AF11,'자율관 배정'!$B:$G,3,FALSE)&"("&VLOOKUP(AF11,'자율관 배정'!$B:$F,2,FALSE)&")","")
B13: 2B024 | C13: 2B023 | D13: 2B022 | E13: 2B021 | F13: 2B020 | H13: 2B019 | I13: 2B018 | J13: 2B017 | K13: 2B016 | L13: 2B015 | O13: 2B014 | P13: 2B013 | Q13: 2B012 | R13: 2B011 | S13: 2B010 | V13: 2C015 | W13: 2C014 | X13: 2C013 | Y13: 2C012 | Z13: 2C011 | AB13: 2C010 | AC13: 2C009 | AD13: 2C008 | AE13: 2C007 | AF13: 2C006
B14: =IFERROR(VLOOKUP(B13,'자율관 배정'!$B:$G,3,FALSE)&"("&VLOOKUP(B13,'자율관 배정'!$B:$F,2,FALSE)&")","") | C14: =IFERROR(VLOOKUP(C13,'자율관 배정'!$B:$G,3,FALSE)&"("&VLOOKUP(C13,'자율관 배정'!$B:$F,2,FALSE)&")","") -> () | D14: =IFERROR(VLOOKUP(D13,'자율관 배정'!$B:$G,3,FALSE)&"("&VLOOKUP(D13,'자율관 배정'!$B:$F,2,FALSE)&")","") | E14: =IFERROR(VLOOKUP(E13,'자율관 배정'!$B:$G,3,FALSE)&"("&VLOOKUP(E13,'자율관 배정'!$B:$F,2,FALSE)&")","") -> () | F14: =IFERROR(VLOOKUP(F13,'자율관 배정'!$B:$G,3,FALSE)&"("&VLOOKUP(F13,'자율관 배정'!$B:$F,2,FALSE)&")","") | H14: =IFERROR(VLOOKUP(H13,'자율관 배정'!$B:$G,3,FALSE)&"("&VLOOKUP(H13,'자율관 배정'!$B:$F,2,FALSE)&")","") -> () | I14: =IFERROR(VLOOKUP(I13,'자율관 배정'!$B:$G,3,FALSE)&"("&VLOOKUP(I13,'자율관 배정'!$B:$F,2,FALSE)&")","") | J14: =IFERROR(VLOOKUP(J13,'자율관 배정'!$B:$G,3,FALSE)&"("&VLOOKUP(J13,'자율관 배정'!$B:$F,2,FALSE)&")","") -> () | K14: =IFERROR(VLOOKUP(K13,'자율관 배정'!$B:$G,3,FALSE)&"("&VLOOKUP(K13,'자율관 배정'!$B:$F,2,FALSE)&")","") | L14: =IFERROR(VLOOKUP(L13,'자율관 배정'!$B:$G,3,FALSE)&"("&VLOOKUP(L13,'자율관 배정'!$B:$F,2,FALSE)&")","") -> () | O14: =IFERROR(VLOOKUP(O13,'자율관 배정'!$B:$G,3,FALSE)&"("&VLOOKUP(O13,'자율관 배정'!$B:$F,2,FALSE)&")","") | P14: =IFERROR(VLOOKUP(P13,'자율관 배정'!$B:$G,3,FALSE)&"("&VLOOKUP(P13,'자율관 배정'!$B:$F,2,FALSE)&")","") -> () | Q14: =IFERROR(VLOOKUP(Q13,'자율관 배정'!$B:$G,3,FALSE)&"("&VLOOKUP(Q13,'자율관 배정'!$B:$F,2,FALSE)&")","") | R14: =IFERROR(VLOOKUP(R13,'자율관 배정'!$B:$G,3,FALSE)&"("&VLOOKUP(R13,'자율관 배정'!$B:$F,2,FALSE)&")","") -> () | S14: =IFERROR(VLOOKUP(S13,'자율관 배정'!$B:$G,3,FALSE)&"("&VLOOKUP(S13,'자율관 배정'!$B:$F,2,FALSE)&")","") | V14: =IFERROR(VLOOKUP(V13,'자율관 배정'!$B:$G,3,FALSE)&"("&VLOOKUP(V13,'자율관 배정'!$B:$F,2,FALSE)&")","") | W14: =IFERROR(VLOOKUP(W13,'자율관 배정'!$B:$G,3,FALSE)&"("&VLOOKUP(W13,'자율관 배정'!$B:$F,2,FALSE)&")","") -> () | X14: =IFERROR(VLOOKUP(X13,'자율관 배정'!$B:$G,3,FALSE)&"("&VLOOKUP(X13,'자율관 배정'!$B:$F,2,FALSE)&")","") | Y14: =IFERROR(VLOOKUP(Y13,'자율관 배정'!$B:$G,3,FALSE)&"("&VLOOKUP(Y13,'자율관 배정'!$B:$F,2,FALSE)&")","") -> () | Z14: =IFERROR(VLOOKUP(Z13,'자율관 배정'!$B:$G,3,FALSE)&"("&VLOOKUP(Z13,'자율관 배정'!$B:$F,2,FALSE)&")","") | AB14: =IFERROR(VLOOKUP(AB13,'자율관 배정'!$B:$G,3,FALSE)&"("&VLOOKUP(AB13,'자율관 배정'!$B:$F,2,FALSE)&")","") -> () | AC14: =IFERROR(VLOOKUP(AC13,'자율관 배정'!$B:$G,3,FALSE)&"("&VLOOKUP(AC13,'자율관 배정'!$B:$F,2,FALSE)&")","") | AD14: =IFERROR(VLOOKUP(AD13,'자율관 배정'!$B:$G,3,FALSE)&"("&VLOOKUP(AD13,'자율관 배정'!$B:$F,2,FALSE)&")","") -> () | AE14: =IFERROR(VLOOKUP(AE13,'자율관 배정'!$B:$G,3,FALSE)&"("&VLOOKUP(AE13,'자율관 배정'!$B:$F,2,FALSE)&")","") | AF14: =IFERROR(VLOOKUP(AF13,'자율관 배정'!$B:$G,3,FALSE)&"("&VLOOKUP(AF13,'자율관 배정'!$B:$F,2,FALSE)&")","") -> ()
B16: 2B009 | C16: 2B008 | D16: 2B007 | E16: 2B006 | F16: 2B005 | I16: 2B004 | J16: 2B003 | K16: 2B002 | L16: 2B001 | V16: 2C005 | W16: 2C004 | X16: 2C003 | AE16: 2C002 | AF16: 2C001
B17: =IFERROR(VLOOKUP(B16,'자율관 배정'!$B:$G,3,FALSE)&"("&VLOOKUP(B16,'자율관 배정'!$B:$F,2,FALSE)&")","") -> () | C17: =IFERROR(VLOOKUP(C16,'자율관 배정'!$B:$G,3,FALSE)&"("&VLOOKUP(C16,'자율관 배정'!$B:$F,2,FALSE)&")","") | D17: =IFERROR(VLOOKUP(D16,'자율관 배정'!$B:$G,3,FALSE)&"("&VLOOKUP(D16,'자율관 배정'!$B:$F,2,FALSE)&")","") -> () | E17: =IFERROR(VLOOKUP(E16,'자율관 배정'!$B:$G,3,FALSE)&"("&VLOOKUP(E16,'자율관 배정'!$B:$F,2,FALSE)&")","") | F17: =IFERROR(VLOOKUP(F16,'자율관 배정'!$B:$G,3,FALSE)&"("&VLOOKUP(F16,'자율관 배정'!$B:$F,2,FALSE)&")","") -> () | I17: =IFERROR(VLOOKUP(I16,'자율관 배정'!$B:$G,3,FALSE)&"("&VLOOKUP(I16,'자율관 배정'!$B:$F,2,FALSE)&")","") -> () | J17: =IFERROR(VLOOKUP(J16,'자율관 배정'!$B:$G,3,FALSE)&"("&VLOOKUP(J16,'자율관 배정'!$B:$F,2,FALSE)&")","") | K17: =IFERROR(VLOOKUP(K16,'자율관 배정'!$B:$G,3,FALSE)&"("&VLOOKUP(K16,'자율관 배정'!$B:$F,2,FALSE)&")","") -> () | L17: =IFERROR(VLOOKUP(L16,'자율관 배정'!$B:$G,3,FALSE)&"("&VLOOKUP(L16,'자율관 배정'!$B:$F,2,FALSE)&")","") | V17: =IFERROR(VLOOKUP(V16,'자율관 배정'!$B:$G,3,FALSE)&"("&VLOOKUP(V16,'자율관 배정'!$B:$F,2,FALSE)&")","") -> () | W17: =IFERROR(VLOOKUP(W16,'자율관 배정'!$B:$G,3,FALSE)&"("&VLOOKUP(W16,'자율관 배정'!$B:$F,2,FALSE)&")","") | X17: =IFERROR(VLOOKUP(X16,'자율관 배정'!$B:$G,3,FALSE)&"("&VLOOKUP(X16,'자율관 배정'!$B:$F,2,FALSE)&")","") -> () | AE17: =IFERROR(VLOOKUP(AE16,'자율관 배정'!$B:$G,3,FALSE)&"("&VLOOKUP(AE16,'자율관 배정'!$B:$F,2,FALSE)&")","") -> () | AF17: =IFERROR(VLOOKUP(AF16,'자율관 배정'!$B:$G,3,FALSE)&"("&VLOOKUP(AF16,'자율관 배정'!$B:$F,2,FALSE)&")","")
Q19: 출입문 | AB19: 출입문
B20: 2A101 | C20: =IFERROR(VLOOKUP(B20,'자율관 배정'!$B:$G,3,FALSE)&"("&VLOOKUP(B20,'자율관 배정'!$B:$F,2,FALSE)&")","") -> () | E20: 2A100 | F20: 2A099 | G20: 2A098 | I20: 2A097 | J20: 2A096 | K20: 2A095 | L20: 2A094 | M20: 2A093 | N20: 2A092 | Q20: 출입문 | AB20: 출입문
B21: 2A102 | C21: =IFERROR(VLOOKUP(B21,'자율관 배정'!$B:$G,3,FALSE)&"("&VLOOKUP(B21,'자율관 배정'!$B:$F,2,FALSE)&")","") | E21: =IFERROR(VLOOKUP(E20,'자율관 배정'!$B:$G,3,FALSE)&"("&VLOOKUP(E20,'자율관 배정'!$B:$F,2,FALSE)&")","") | F21: =IFERROR(VLOOKUP(F20,'자율관 배정'!$B:$G,3,FALSE)&"("&VLOOKUP(F20,'자율관 배정'!$B:$F,2,FALSE)&")","") -> () | G21: =IFERROR(VLOOKUP(G20,'자율관 배정'!$B:$G,3,FALSE)&"("&VLOOKUP(G20,'자율관 배정'!$B:$F,2,FALSE)&")","") | I21: =IFERROR(VLOOKUP(I20,'자율관 배정'!$B:$G,3,FALSE)&"("&VLOOKUP(I20,'자율관 배정'!$B:$F,2,FALSE)&")","") -> () | J21: =IFERROR(VLOOKUP(J20,'자율관 배정'!$B:$G,3,FALSE)&"("&VLOOKUP(J20,'자율관 배정'!$B:$F,2,FALSE)&")","") | K21: =IFERROR(VLOOKUP(K20,'자율관 배정'!$B:$G,3,FALSE)&"("&VLOOKUP(K20,'자율관 배정'!$B:$F,2,FALSE)&")","") -> () | L21: =IFERROR(VLOOKUP(L20,'자율관 배정'!$B:$G,3,FALSE)&"("&VLOOKUP(L20,'자율관 배정'!$B:$F,2,FALSE)&")","") | M21: =IFERROR(VLOOKUP(M20,'자율관 배정'!$B:$G,3,FALSE)&"("&VLOOKUP(M20,'자율관 배정'!$B:$F,2,FALSE)&")","") -> () | N21: =IFERROR(VLOOKUP(N20,'자율관 배정'!$B:$G,3,FALSE)&"("&VLOOKUP(N20,'자율관 배정'!$B:$F,2,FALSE)&")","")
B22: 2A103 | C22: =IFERROR(VLOOKUP(B22,'자율관 배정'!$B:$G,3,FALSE)&"("&VLOOKUP(B22,'자율관 배정'!$B:$F,2,FALSE)&")","") -> () | E22: 2A091 | F22: 2A090 | G22: 2A089 | I22: 2A088 | J22: 2A087 | K22: 2A086 | L22: 2A085 | M22: 2A084 | N22: 2A083
B23: 2A104 | C23: =IFERROR(VLOOKUP(B23,'자율관 배정'!$B:$G,3,FALSE)&"("&VLOOKUP(B23,'자율관 배정'!$B:$F,2,FALSE)&")","") | E23: =IFERROR(VLOOKUP(E22,'자율관 배정'!$B:$G,3,FALSE)&"("&VLOOKUP(E22,'자율관 배정'!$B:$F,2,FALSE)&")","") -> () | F23: =IFERROR(VLOOKUP(F22,'자율관 배정'!$B:$G,3,FALSE)&"("&VLOOKUP(F22,'자율관 배정'!$B:$F,2,FALSE)&")","") | G23: =IFERROR(VLOOKUP(G22,'자율관 배정'!$B:$G,3,FALSE)&"("&VLOOKUP(G22,'자율관 배정'!$B:$F,2,FALSE)&")","") -> () | I23: =IFERROR(VLOOKUP(I22,'자율관 배정'!$B:$G,3,FALSE)&"("&VLOOKUP(I22,'자율관 배정'!$B:$F,2,FALSE)&")","") | J23: =IFERROR(VLOOKUP(J22,'자율관 배정'!$B:$G,3,FALSE)&"("&VLOOKUP(J22,'자율관 배정'!$B:$F,2,FALSE)&")","") -> () | K23: =IFERROR(VLOOKUP(K22,'자율관 배정'!$B:$G,3,FALSE)&"("&VLOOKUP(K22,'자율관 배정'!$B:$F,2,FALSE)&")","") | L23: =IFERROR(VLOOKUP(L22,'자율관 배정'!$B:$G,3,FALSE)&"("&VLOOKUP(L22,'자율관 배정'!$B:$F,2,FALSE)&")","") -> () | M23: =IFERROR(VLOOKUP(M22,'자율관 배정'!$B:$G,3,FALSE)&"("&VLOOKUP(M22,'자율관 배정'!$B:$F,2,FALSE)&")","") | N23: =IFERROR(VLOOKUP(N22,'자율관 배정'!$B:$G,3,FALSE)&"("&VLOOKUP(N22,'자율관 배정'!$B:$F,2,FALSE)&")","") -> () | U23: 2D122 | V23: 2D121 | W23: 2D120 | X23: 2D119 | Y23: 2D118 | Z23: 2D117 | AB23: 2D116 | AC23: 2D115 | AD23: 2D114 | AE23: 2D113 | AF23: 2D112
B24: 2A105 | C24: =IFERROR(VLOOKUP(B24,'자율관 배정'!$B:$G,3,FALSE)&"("&VLOOKUP(B24,'자율관 배정'!$B:$F,2,FALSE)&")","") -> () | U24: =IFERROR(VLOOKUP(U23,'자율관 배정'!$B:$G,3,FALSE)&"("&VLOOKUP(U23,'자율관 배정'!$B:$F,2,FALSE)&")","") | V24: =IFERROR(VLOOKUP(V23,'자율관 배정'!$B:$G,3,FALSE)&"("&VLOOKUP(V23,'자율관 배정'!$B:$F,2,FALSE)&")","") -> () | W24: =IFERROR(VLOOKUP(W23,'자율관 배정'!$B:$G,3,FALSE)&"("&VLOOKUP(W23,'자율관 배정'!$B:$F,2,FALSE)&")","") | X24: =IFERROR(VLOOKUP(X23,'자율관 배정'!$B:$G,3,FALSE)&"("&VLOOKUP(X23,'자율관 배정'!$B:$F,2,FALSE)&")","") -> () | Y24: =IFERROR(VLOOKUP(Y23,'자율관 배정'!$B:$G,3,FALSE)&"("&VLOOKUP(Y23,'자율관 배정'!$B:$F,2,FALSE)&")","") | Z24: =IFERROR(VLOOKUP(Z23,'자율관 배정'!$B:$G,3,FALSE)&"("&VLOOKUP(Z23,'자율관 배정'!$B:$F,2,FALSE)&")","") -> () | AB24: =IFERROR(VLOOKUP(AB23,'자율관 배정'!$B:$G,3,FALSE)&"("&VLOOKUP(AB23,'자율관 배정'!$B:$F,2,FALSE)&")","") | AC24: =IFERROR(VLOOKUP(AC23,'자율관 배정'!$B:$G,3,FALSE)&"("&VLOOKUP(AC23,'자율관 배정'!$B:$F,2,FALSE)&")","") -> () | AD24: =IFERROR(VLOOKUP(AD23,'자율관 배정'!$B:$G,3,FALSE)&"("&VLOOKUP(AD23,'자율관 배정'!$B:$F,2,FALSE)&")","") | AE24: =IFERROR(VLOOKUP(AE23,'자율관 배정'!$B:$G,3,FALSE)&"("&VLOOKUP(AE23,'자율관 배정'!$B:$F,2,FALSE)&")","") -> () | AF24: =IFERROR(VLOOKUP(AF23,'자율관 배정'!$B:$G,3,FALSE)&"("&VLOOKUP(AF23,'자율관 배정'!$B:$F,2,FALSE)&")","")
B25: 2A106 | C25: =IFERROR(VLOOKUP(B25,'자율관 배정'!$B:$G,3,FALSE)&"("&VLOOKUP(B25,'자율관 배정'!$B:$F,2,FALSE)&")","") | E25: 2A082 | F25: 2A081 | G25: 2A080 | I25: 2A079 | J25: 2A078 | K25: 2A077 | L25: 2A076 | M25: 2A075 | N25: 2A074 | U25: 2D111 | V25: 2D110 | W25: 2D109 | X25: 2D108 | Y25: 2D107 | Z25: 2D106 | AB25: 2D105 | AC25: 2D104 | AD25: 2D103 | AE25: 2D102 | AF25: 2D101
B26: 2A107 | C26: =IFERROR(VLOOKUP(B26,'자율관 배정'!$B:$G,3,FALSE)&"("&VLOOKUP(B26,'자율관 배정'!$B:$F,2,FALSE)&")","") -> () | E26: =IFERROR(VLOOKUP(E25,'자율관 배정'!$B:$G,3,FALSE)&"("&VLOOKUP(E25,'자율관 배정'!$B:$F,2,FALSE)&")","") | F26: =IFERROR(VLOOKUP(F25,'자율관 배정'!$B:$G,3,FALSE)&"("&VLOOKUP(F25,'자율관 배정'!$B:$F,2,FALSE)&")","") -> () | G26: =IFERROR(VLOOKUP(G25,'자율관 배정'!$B:$G,3,FALSE)&"("&VLOOKUP(G25,'자율관 배정'!$B:$F,2,FALSE)&")","") | I26: =IFERROR(VLOOKUP(I25,'자율관 배정'!$B:$G,3,FALSE)&"("&VLOOKUP(I25,'자율관 배정'!$B:$F,2,FALSE)&")","") -> () | J26: =IFERROR(VLOOKUP(J25,'자율관 배정'!$B:$G,3,FALSE)&"("&VLOOKUP(J25,'자율관 배정'!$B:$F,2,FALSE)&")","") | K26: =IFERROR(VLOOKUP(K25,'자율관 배정'!$B:$G,3,FALSE)&"("&VLOOKUP(K25,'자율관 배정'!$B:$F,2,FALSE)&")","") -> () | L26: =IFERROR(VLOOKUP(L25,'자율관 배정'!$B:$G,3,FALSE)&"("&VLOOKUP(L25,'자율관 배정'!$B:$F,2,FALSE)&")","") | M26: =IFERROR(VLOOKUP(M25,'자율관 배정'!$B:$G,3,FALSE)&"("&VLOOKUP(M25,'자율관 배정'!$B:$F,2,FALSE)&")","") -> () | N26: =IFERROR(VLOOKUP(N25,'자율관 배정'!$B:$G,3,FALSE)&"("&VLOOKUP(N25,'자율관 배정'!$B:$F,2,FALSE)&")","") | T26: 출 입 문 | U26: =IFERROR(VLOOKUP(U25,'자율관 배정'!$B:$G,3,FALSE)&"("&VLOOKUP(U25,'자율관 배정'!$B:$F,2,FALSE)&")","") -> () | V26: =IFERROR(VLOOKUP(V25,'자율관 배정'!$B:$G,3,FALSE)&"("&VLOOKUP(V25,'자율관 배정'!$B:$F,2,FALSE)&")","") | W26: =IFERROR(VLOOKUP(W25,'자율관 배정'!$B:$G,3,FALSE)&"("&VLOOKUP(W25,'자율관 배정'!$B:$F,2,FALSE)&")","") -> () | X26: =IFERROR(VLOOKUP(X25,'자율관 배정'!$B:$G,3,FALSE)&"("&VLOOKUP(X25,'자율관 배정'!$B:$F,2,FALSE)&")","") | Y26: =IFERROR(VLOOKUP(Y25,'자율관 배정'!$B:$G,3,FALSE)&"("&VLOOKUP(Y25,'자율관 배정'!$B:$F,2,FALSE)&")","") -> () | Z26: =IFERROR(VLOOKUP(Z25,'자율관 배정'!$B:$G,3,FALSE)&"("&VLOOKUP(Z25,'자율관 배정'!$B:$F,2,FALSE)&")","") | AB26: =IFERROR(VLOOKUP(AB25,'자율관 배정'!$B:$G,3,FALSE)&"("&VLOOKUP(AB25,'자율관 배정'!$B:$F,2,FALSE)&")","") -> () | AC26: =IFERROR(VLOOKUP(AC25,'자율관 배정'!$B:$G,3,FALSE)&"("&VLOOKUP(AC25,'자율관 배정'!$B:$F,2,FALSE)&")","") | AD26: =IFERROR(VLOOKUP(AD25,'자율관 배정'!$B:$G,3,FALSE)&"("&VLOOKUP(AD25,'자율관 배정'!$B:$F,2,FALSE)&")","") -> () | AE26: =IFERROR(VLOOKUP(AE25,'자율관 배정'!$B:$G,3,FALSE)&"("&VLOOKUP(AE25,'자율관 배정'!$B:$F,2,FALSE)&")","") | AF26: =IFERROR(VLOOKUP(AF25,'자율관 배정'!$B:$G,3,FALSE)&"("&VLOOKUP(AF25,'자율관 배정'!$B:$F,2,FALSE)&")","") -> ()
B27: 2A108 | C27: =IFERROR(VLOOKUP(B27,'자율관 배정'!$B:$G,3,FALSE)&"("&VLOOKUP(B27,'자율관 배정'!$B:$F,2,FALSE)&")","") | E27: 2A073 | F27: 2A072 | G27: 2A071 | I27: 2A070 | J27: 2A069 | K27: 2A068 | L27: 2A067 | M27: 2A066 | N27: 2A065
B28: 2A109 | C28: =IFERROR(VLOOKUP(B28,'자율관 배정'!$B:$G,3,FALSE)&"("&VLOOKUP(B28,'자율관 배정'!$B:$F,2,FALSE)&")","") -> () | E28: =IFERROR(VLOOKUP(E27,'자율관 배정'!$B:$G,3,FALSE)&"("&VLOOKUP(E27,'자율관 배정'!$B:$F,2,FALSE)&")","") -> () | F28: =IFERROR(VLOOKUP(F27,'자율관 배정'!$B:$G,3,FALSE)&"("&VLOOKUP(F27,'자율관 배정'!$B:$F,2,FALSE)&")","") | G28: =IFERROR(VLOOKUP(G27,'자율관 배정'!$B:$G,3,FALSE)&"("&VLOOKUP(G27,'자율관 배정'!$B:$F,2,FALSE)&")","") -> () | I28: =IFERROR(VLOOKUP(I27,'자율관 배정'!$B:$G,3,FALSE)&"("&VLOOKUP(I27,'자율관 배정'!$B:$F,2,FALSE)&")","") | J28: =IFERROR(VLOOKUP(J27,'자율관 배정'!$B:$G,3,FALSE)&"("&VLOOKUP(J27,'자율관 배정'!$B:$F,2,FALSE)&")","") -> () | K28: =IFERROR(VLOOKUP(K27,'자율관 배정'!$B:$G,3,FALSE)&"("&VLOOKUP(K27,'자율관 배정'!$B:$F,2,FALSE)&")","") | L28: =IFERROR(VLOOKUP(L27,'자율관 배정'!$B:$G,3,FALSE)&"("&VLOOKUP(L27,'자율관 배정'!$B:$F,2,FALSE)&")","") -> () | M28: =IFERROR(VLOOKUP(M27,'자율관 배정'!$B:$G,3,FALSE)&"("&VLOOKUP(M27,'자율관 배정'!$B:$F,2,FALSE)&")","") | N28: =IFERROR(VLOOKUP(N27,'자율관 배정'!$B:$G,3,FALSE)&"("&VLOOKUP(N27,'자율관 배정'!$B:$F,2,FALSE)&")","") -> () | P28: 출 입 문 | U28: 2D100 | V28: 2D099 | W28: 2D098 | X28: 2D097 | Y28: 2D096 | Z28: 2D095 | AB28: 2D094 | AC28: 2D093 | AD28: 2D092 | AE28: 2D091 | AF28: 2D090
B29: 벽 | U29: =IFERROR(VLOOKUP(U28,'자율관 배정'!$B:$G,3,FALSE)&"("&VLOOKUP(U28,'자율관 배정'!$B:$F,2,FALSE)&")","") | V29: =IFERROR(VLOOKUP(V28,'자율관 배정'!$B:$G,3,FALSE)&"("&VLOOKUP(V28,'자율관 배정'!$B:$F,2,FALSE)&")","") -> () | W29: =IFERROR(VLOOKUP(W28,'자율관 배정'!$B:$G,3,FALSE)&"("&VLOOKUP(W28,'자율관 배정'!$B:$F,2,FALSE)&")","") | X29: =IFERROR(VLOOKUP(X28,'자율관 배정'!$B:$G,3,FALSE)&"("&VLOOKUP(X28,'자율관 배정'!$B:$F,2,FALSE)&")","") -> () | Y29: =IFERROR(VLOOKUP(Y28,'자율관 배정'!$B:$G,3,FALSE)&"("&VLOOKUP(Y28,'자율관 배정'!$B:$F,2,FALSE)&")","") | Z29: =IFERROR(VLOOKUP(Z28,'자율관 배정'!$B:$G,3,FALSE)&"("&VLOOKUP(Z28,'자율관 배정'!$B:$F,2,FALSE)&")","") -> () | AB29: =IFERROR(VLOOKUP(AB28,'자율관 배정'!$B:$G,3,FALSE)&"("&VLOOKUP(AB28,'자율관 배정'!$B:$F,2,FALSE)&")","") | AC29: =IFERROR(VLOOKUP(AC28,'자율관 배정'!$B:$G,3,FALSE)&"("&VLOOKUP(AC28,'자율관 배정'!$B:$F,2,FALSE)&")","") -> () | AD29: =IFERROR(VLOOKUP(AD28,'자율관 배정'!$B:$G,3,FALSE)&"("&VLOOKUP(AD28,'자율관 배정'!$B:$F,2,FALSE)&")","") | AE29: =IFERROR(VLOOKUP(AE28,'자율관 배정'!$B:$G,3,FALSE)&"("&VLOOKUP(AE28,'자율관 배정'!$B:$F,2,FALSE)&")","") -> () | AF29: =IFERROR(VLOOKUP(AF28,'자율관 배정'!$B:$G,3,FALSE)&"("&VLOOKUP(AF28,'자율관 배정'!$B:$F,2,FALSE)&")","")
E30: 2A064 | F30: 2A063 | G30: 2A062 | J30: 2A061 | K30: 2A060 | L30: 2A059 | M30: 2A058 | U30: 2D089 | V30: 2D088 | W30: 2D087 | X30: 2D086 | Y30: 2D085 | Z30: 2D084 | AB30: 2D083 | AE30: 2D082 | AF30: 2D081
E31: =IFERROR(VLOOKUP(E30,'자율관 배정'!$B:$G,3,FALSE)&"("&VLOOKUP(E30,'자율관 배정'!$B:$F,2,FALSE)&")","") | F31: =IFERROR(VLOOKUP(F30,'자율관 배정'!$B:$G,3,FALSE)&"("&VLOOKUP(F30,'자율관 배정'!$B:$F,2,FALSE)&")","") -> () | G31: =IFERROR(VLOOKUP(G30,'자율관 배정'!$B:$G,3,FALSE)&"("&VLOOKUP(G30,'자율관 배정'!$B:$F,2,FALSE)&")","") | J31: =IFERROR(VLOOKUP(J30,'자율관 배정'!$B:$G,3,FALSE)&"("&VLOOKUP(J30,'자율관 배정'!$B:$F,2,FALSE)&")","") | K31: =IFERROR(VLOOKUP(K30,'자율관 배정'!$B:$G,3,FALSE)&"("&VLOOKUP(K30,'자율관 배정'!$B:$F,2,FALSE)&")","") -> () | L31: =IFERROR(VLOOKUP(L30,'자율관 배정'!$B:$G,3,FALSE)&"("&VLOOKUP(L30,'자율관 배정'!$B:$F,2,FALSE)&")","") | M31: =IFERROR(VLOOKUP(M30,'자율관 배정'!$B:$G,3,FALSE)&"("&VLOOKUP(M30,'자율관 배정'!$B:$F,2,FALSE)&")","") -> () | U31: =IFERROR(VLOOKUP(U30,'자율관 배정'!$B:$G,3,FALSE)&"("&VLOOKUP(U30,'자율관 배정'!$B:$F,2,FALSE)&")","") -> () | V31: =IFERROR(VLOOKUP(V30,'자율관 배정'!$B:$G,3,FALSE)&"("&VLOOKUP(V30,'자율관 배정'!$B:$F,2,FALSE)&")","") | W31: =IFERROR(VLOOKUP(W30,'자율관 배정'!$B:$G,3,FALSE)&"("&VLOOKUP(W30,'자율관 배정'!$B:$F,2,FALSE)&")","") -> () | X31: =IFERROR(VLOOKUP(X30,'자율관 배정'!$B:$G,3,FALSE)&"("&VLOOKUP(X30,'자율관 배정'!$B:$F,2,FALSE)&")","") | Y31: =IFERROR(VLOOKUP(Y30,'자율관 배정'!$B:$G,3,FALSE)&"("&VLOOKUP(Y30,'자율관 배정'!$B:$F,2,FALSE)&")","") -> () | Z31: =IFERROR(VLOOKUP(Z30,'자율관 배정'!$B:$G,3,FALSE)&"("&VLOOKUP(Z30,'자율관 배정'!$B:$F,2,FALSE)&")","") | AB31: =IFERROR(VLOOKUP(AB30,'자율관 배정'!$B:$G,3,FALSE)&"("&VLOOKUP(AB30,'자율관 배정'!$B:$F,2,FALSE)&")","") -> () | AE31: =IFERROR(VLOOKUP(AE30,'자율관 배정'!$B:$G,3,FALSE)&"("&VLOOKUP(AE30,'자율관 배정'!$B:$F,2,FALSE)&")","") | AF31: =IFERROR(VLOOKUP(AF30,'자율관 배정'!$B:$G,3,FALSE)&"("&VLOOKUP(AF30,'자율관 배정'!$B:$F,2,FALSE)&")","") -> ()
E32: 2A057 | F32: 2A056 | G32: 2A055 | J32: 2A054 | K32: 2A053 | L32: 2A052 | M32: 2A051
E33: =IFERROR(VLOOKUP(E32,'자율관 배정'!$B:$G,3,FALSE)&"("&VLOOKUP(E32,'자율관 배정'!$B:$F,2,FALSE)&")","") -> () | F33: =IFERROR(VLOOKUP(F32,'자율관 배정'!$B:$G,3,FALSE)&"("&VLOOKUP(F32,'자율관 배정'!$B:$F,2,FALSE)&")","") | G33: =IFERROR(VLOOKUP(G32,'자율관 배정'!$B:$G,3,FALSE)&"("&VLOOKUP(G32,'자율관 배정'!$B:$F,2,FALSE)&")","") -> () | J33: =IFERROR(VLOOKUP(J32,'자율관 배정'!$B:$G,3,FALSE)&"("&VLOOKUP(J32,'자율관 배정'!$B:$F,2,FALSE)&")","") -> () | K33: =IFERROR(VLOOKUP(K32,'자율관 배정'!$B:$G,3,FALSE)&"("&VLOOKUP(K32,'자율관 배정'!$B:$F,2,FALSE)&")","") | L33: =IFERROR(VLOOKUP(L32,'자율관 배정'!$B:$G,3,FALSE)&"("&VLOOKUP(L32,'자율관 배정'!$B:$F,2,FALSE)&")","") -> () | M33: =IFERROR(VLOOKUP(M32,'자율관 배정'!$B:$G,3,FALSE)&"("&VLOOKUP(M32,'자율관 배정'!$B:$F,2,FALSE)&")","") | U33: 2D080 | V33: 2D079 | W33: 2D078 | X33: 2D077 | Y33: 2D076 | Z33: 2D075 | AB33: 2D074 | AC33: 2D073 | AD33: 2D072 | AE33: 2D071 | AF33: 2D070
U34: =IFERROR(VLOOKUP(U33,'자율관 배정'!$B:$G,3,FALSE)&"("&VLOOKUP(U33,'자율관 배정'!$B:$F,2,FALSE)&")","") | V34: =IFERROR(VLOOKUP(V33,'자율관 배정'!$B:$G,3,FALSE)&"("&VLOOKUP(V33,'자율관 배정'!$B:$F,2,FALSE)&")","") -> () | W34: =IFERROR(VLOOKUP(W33,'자율관 배정'!$B:$G,3,FALSE)&"("&VLOOKUP(W33,'자율관 배정'!$B:$F,2,FALSE)&")","") | X34: =IFERROR(VLOOKUP(X33,'자율관 배정'!$B:$G,3,FALSE)&"("&VLOOKUP(X33,'자율관 배정'!$B:$F,2,FALSE)&")","") -> () | Y34: =IFERROR(VLOOKUP(Y33,'자율관 배정'!$B:$G,3,FALSE)&"("&VLOOKUP(Y33,'자율관 배정'!$B:$F,2,FALSE)&")","") | Z34: =IFERROR(VLOOKUP(Z33,'자율관 배정'!$B:$G,3,FALSE)&"("&VLOOKUP(Z33,'자율관 배정'!$B:$F,2,FALSE)&")","") -> () | AB34: =IFERROR(VLOOKUP(AB33,'자율관 배정'!$B:$G,3,FALSE)&"("&VLOOKUP(AB33,'자율관 배정'!$B:$F,2,FALSE)&")","") | AC34: =IFERROR(VLOOKUP(AC33,'자율관 배정'!$B:$G,3,FALSE)&"("&VLOOKUP(AC33,'자율관 배정'!$B:$F,2,FALSE)&")","") -> () | AD34: =IFERROR(VLOOKUP(AD33,'자율관 배정'!$B:$G,3,FALSE)&"("&VLOOKUP(AD33,'자율관 배정'!$B:$F,2,FALSE)&")","") | AE34: =IFERROR(VLOOKUP(AE33,'자율관 배정'!$B:$G,3,FALSE)&"("&VLOOKUP(AE33,'자율관 배정'!$B:$F,2,FALSE)&")","") -> () | AF34: =IFERROR(VLOOKUP(AF33,'자율관 배정'!$B:$G,3,FALSE)&"("&VLOOKUP(AF33,'자율관 배정'!$B:$F,2,FALSE)&")","")
B35: 2A110 | C35: =IFERROR(VLOOKUP(B35,'자율관 배정'!$B:$G,3,FALSE)&"("&VLOOKUP(B35,'자율관 배정'!$B:$F,2,FALSE)&")","") -> () | E35: 2A050 | F35: 2A049 | G35: 2A048 | I35: 2A047 | J35: 2A046 | K35: 2A045 | L35: 2A044 | M35: 2A043 | N35: 2A042 | U35: 2D069 | V35: 2D068 | W35: 2D067 | X35: 2D066 | Y35: 2D065 | Z35: 2D064 | AB35: 2D063 | AC35: 2D062 | AD35: 2D061 | AE35: 2D060 | AF35: 2D059
B36: 2A111 | C36: =IFERROR(VLOOKUP(B36,'자율관 배정'!$B:$G,3,FALSE)&"("&VLOOKUP(B36,'자율관 배정'!$B:$F,2,FALSE)&")","") | E36: =IFERROR(VLOOKUP(E35,'자율관 배정'!$B:$G,3,FALSE)&"("&VLOOKUP(E35,'자율관 배정'!$B:$F,2,FALSE)&")","") | F36: =IFERROR(VLOOKUP(F35,'자율관 배정'!$B:$G,3,FALSE)&"("&VLOOKUP(F35,'자율관 배정'!$B:$F,2,FALSE)&")","") -> () | G36: =IFERROR(VLOOKUP(G35,'자율관 배정'!$B:$G,3,FALSE)&"("&VLOOKUP(G35,'자율관 배정'!$B:$F,2,FALSE)&")","") | I36: =IFERROR(VLOOKUP(I35,'자율관 배정'!$B:$G,3,FALSE)&"("&VLOOKUP(I35,'자율관 배정'!$B:$F,2,FALSE)&")","") -> () | J36: =IFERROR(VLOOKUP(J35,'자율관 배정'!$B:$G,3,FALSE)&"("&VLOOKUP(J35,'자율관 배정'!$B:$F,2,FALSE)&")","") | K36: =IFERROR(VLOOKUP(K35,'자율관 배정'!$B:$G,3,FALSE)&"("&VLOOKUP(K35,'자율관 배정'!$B:$F,2,FALSE)&")","") -> () | L36: =IFERROR(VLOOKUP(L35,'자율관 배정'!$B:$G,3,FALSE)&"("&VLOOKUP(L35,'자율관 배정'!$B:$F,2,FALSE)&")","") | M36: =IFERROR(VLOOKUP(M35,'자율관 배정'!$B:$G,3,FALSE)&"("&VLOOKUP(M35,'자율관 배정'!$B:$F,2,FALSE)&")","") -> () | N36: =IFERROR(VLOOKUP(N35,'자율관 배정'!$B:$G,3,FALSE)&"("&VLOOKUP(N35,'자율관 배정'!$B:$F,2,FALSE)&")","") | U36: =IFERROR(VLOOKUP(U35,'자율관 배정'!$B:$G,3,FALSE)&"("&VLOOKUP(U35,'자율관 배정'!$B:$F,2,FALSE)&")","") -> () | V36: =IFERROR(VLOOKUP(V35,'자율관 배정'!$B:$G,3,FALSE)&"("&VLOOKUP(V35,'자율관 배정'!$B:$F,2,FALSE)&")","") | W36: =IFERROR(VLOOKUP(W35,'자율관 배정'!$B:$G,3,FALSE)&"("&VLOOKUP(W35,'자율관 배정'!$B:$F,2,FALSE)&")","") -> () | X36: =IFERROR(VLOOKUP(X35,'자율관 배정'!$B:$G,3,FALSE)&"("&VLOOKUP(X35,'자율관 배정'!$B:$F,2,FALSE)&")","") | Y36: =IFERROR(VLOOKUP(Y35,'자율관 배정'!$B:$G,3,FALSE)&"("&VLOOKUP(Y35,'자율관 배정'!$B:$F,2,FALSE)&")","") -> () | Z36: =IFERROR(VLOOKUP(Z35,'자율관 배정'!$B:$G,3,FALSE)&"("&VLOOKUP(Z35,'자율관 배정'!$B:$F,2,FALSE)&")","") | AB36: =IFERROR(VLOOKUP(AB35,'자율관 배정'!$B:$G,3,FALSE)&"("&VLOOKUP(AB35,'자율관 배정'!$B:$F,2,FALSE)&")","") -> () | AC36: =IFERROR(VLOOKUP(AC35,'자율관 배정'!$B:$G,3,FALSE)&"("&VLOOKUP(AC35,'자율관 배정'!$B:$F,2,FALSE)&")","") | AD36: =IFERROR(VLOOKUP(AD35,'자율관 배정'!$B:$G,3,FALSE)&"("&VLOOKUP(AD35,'자율관 배정'!$B:$F,2,FALSE)&")","") -> () | AE36: =IFERROR(VLOOKUP(AE35,'자율관 배정'!$B:$G,3,FALSE)&"("&VLOOKUP(AE35,'자율관 배정'!$B:$F,2,FALSE)&")","") | AF36: =IFERROR(VLOOKUP(AF35,'자율관 배정'!$B:$G,3,FALSE)&"("&VLOOKUP(AF35,'자율관 배정'!$B:$F,2,FALSE)&")","") -> ()
B37: 2A112 | C37: =IFERROR(VLOOKUP(B37,'자율관 배정'!$B:$G,3,FALSE)&"("&VLOOKUP(B37,'자율관 배정'!$B:$F,2,FALSE)&")","") -> () | E37: 2A041 | F37: 2A040 | G37: 2A039 | I37: 2A038 | J37: 2A037 | K37: 2A036 | L37: 2A035 | M37: 2A034 | N37: 2A033
B38: 2A113 | C38: =IFERROR(VLOOKUP(B38,'자율관 배정'!$B:$G,3,FALSE)&"("&VLOOKUP(B38,'자율관 배정'!$B:$F,2,FALSE)&")","") | E38: =IFERROR(VLOOKUP(E37,'자율관 배정'!$B:$G,3,FALSE)&"("&VLOOKUP(E37,'자율관 배정'!$B:$F,2,FALSE)&")","") -> () | F38: =IFERROR(VLOOKUP(F37,'자율관 배정'!$B:$G,3,FALSE)&"("&VLOOKUP(F37,'자율관 배정'!$B:$F,2,FALSE)&")","") | G38: =IFERROR(VLOOKUP(G37,'자율관 배정'!$B:$G,3,FALSE)&"("&VLOOKUP(G37,'자율관 배정'!$B:$F,2,FALSE)&")","") -> () | I38: =IFERROR(VLOOKUP(I37,'자율관 배정'!$B:$G,3,FALSE)&"("&VLOOKUP(I37,'자율관 배정'!$B:$F,2,FALSE)&")","") | J38: =IFERROR(VLOOKUP(J37,'자율관 배정'!$B:$G,3,FALSE)&"("&VLOOKUP(J37,'자율관 배정'!$B:$F,2,FALSE)&")","") -> () | K38: =IFERROR(VLOOKUP(K37,'자율관 배정'!$B:$G,3,FALSE)&"("&VLOOKUP(K37,'자율관 배정'!$B:$F,2,FALSE)&")","") | L38: =IFERROR(VLOOKUP(L37,'자율관 배정'!$B:$G,3,FALSE)&"("&VLOOKUP(L37,'자율관 배정'!$B:$F,2,FALSE)&")","") -> () | M38: =IFERROR(VLOOKUP(M37,'자율관 배정'!$B:$G,3,FALSE)&"("&VLOOKUP(M37,'자율관 배정'!$B:$F,2,FALSE)&")","") | N38: =IFERROR(VLOOKUP(N37,'자율관 배정'!$B:$G,3,FALSE)&"("&VLOOKUP(N37,'자율관 배정'!$B:$F,2,FALSE)&")","") -> () | U38: 2D058 | V38: 2D057 | W38: 2D056 | X38: 2D055 | Y38: 2D054 | Z38: 2D053 | AB38: 2D052 | AC38: 2D051 | AD38: 2D050 | AE38: 2D049 | AF38: 2D048
B39: 2A114 | C39: =IFERROR(VLOOKUP(B39,'자율관 배정'!$B:$G,3,FALSE)&"("&VLOOKUP(B39,'자율관 배정'!$B:$F,2,FALSE)&")","") -> () | U39: =IFERROR(VLOOKUP(U38,'자율관 배정'!$B:$G,3,FALSE)&"("&VLOOKUP(U38,'자율관 배정'!$B:$F,2,FALSE)&")","") | V39: =IFERROR(VLOOKUP(V38,'자율관 배정'!$B:$G,3,FALSE)&"("&VLOOKUP(V38,'자율관 배정'!$B:$F,2,FALSE)&")","") -> () | W39: =IFERROR(VLOOKUP(W38,'자율관 배정'!$B:$G,3,FALSE)&"("&VLOOKUP(W38,'자율관 배정'!$B:$F,2,FALSE)&")","") | X39: =IFERROR(VLOOKUP(X38,'자율관 배정'!$B:$G,3,FALSE)&"("&VLOOKUP(X38,'자율관 배정'!$B:$F,2,FALSE)&")","") -> () | Y39: =IFERROR(VLOOKUP(Y38,'자율관 배정'!$B:$G,3,FALSE)&"("&VLOOKUP(Y38,'자율관 배정'!$B:$F,2,FALSE)&")","") | Z39: =IFERROR(VLOOKUP(Z38,'자율관 배정'!$B:$G,3,FALSE)&"("&VLOOKUP(Z38,'자율관 배정'!$B:$F,2,FALSE)&")","") -> () | AB39: =IFERROR(VLOOKUP(AB38,'자율관 배정'!$B:$G,3,FALSE)&"("&VLOOKUP(AB38,'자율관 배정'!$B:$F,2,FALSE)&")","") | AC39: =IFERROR(VLOOKUP(AC38,'자율관 배정'!$B:$G,3,FALSE)&"("&VLOOKUP(AC38,'자율관 배정'!$B:$F,2,FALSE)&")","") -> () | AD39: =IFERROR(VLOOKUP(AD38,'자율관 배정'!$B:$G,3,FALSE)&"("&VLOOKUP(AD38,'자율관 배정'!$B:$F,2,FALSE)&")","") | AE39: =IFERROR(VLOOKUP(AE38,'자율관 배정'!$B:$G,3,FALSE)&"("&VLOOKUP(AE38,'자율관 배정'!$B:$F,2,FALSE)&")","") -> () | AF39: =IFERROR(VLOOKUP(AF38,'자율관 배정'!$B:$G,3,FALSE)&"("&VLOOKUP(AF38,'자율관 배정'!$B:$F,2,FALSE)&")","")
B40: 2A115 | C40: =IFERROR(VLOOKUP(B40,'자율관 배정'!$B:$G,3,FALSE)&"("&VLOOKUP(B40,'자율관 배정'!$B:$F,2,FALSE)&")","") | E40: 2A032 | F40: 2A031 | G40: 2A030 | I40: 2A029 | J40: 2A028 | K40: 2A027 | L40: 2A026 | M40: 2A025 | N40: 2A024 | U40: 2D047 | V40: 2D046 | W40: 2D045 | X40: 2D044 | Y40: 2D043 | Z40: 2D042 | AB40: 2D041 | AC40: 2D040 | AD40: 2D039 | AE40: 2D038 | AF40: 2D037
B41: 2A116 | C41: =IFERROR(VLOOKUP(B41,'자율관 배정'!$B:$G,3,FALSE)&"("&VLOOKUP(B41,'자율관 배정'!$B:$F,2,FALSE)&")","") -> () | E41: =IFERROR(VLOOKUP(E40,'자율관 배정'!$B:$G,3,FALSE)&"("&VLOOKUP(E40,'자율관 배정'!$B:$F,2,FALSE)&")","") | F41: =IFERROR(VLOOKUP(F40,'자율관 배정'!$B:$G,3,FALSE)&"("&VLOOKUP(F40,'자율관 배정'!$B:$F,2,FALSE)&")","") -> () | G41: =IFERROR(VLOOKUP(G40,'자율관 배정'!$B:$G,3,FALSE)&"("&VLOOKUP(G40,'자율관 배정'!$B:$F,2,FALSE)&")","") | I41: =IFERROR(VLOOKUP(I40,'자율관 배정'!$B:$G,3,FALSE)&"("&VLOOKUP(I40,'자율관 배정'!$B:$F,2,FALSE)&")","") -> () | J41: =IFERROR(VLOOKUP(J40,'자율관 배정'!$B:$G,3,FALSE)&"("&VLOOKUP(J40,'자율관 배정'!$B:$F,2,FALSE)&")","") | K41: =IFERROR(VLOOKUP(K40,'자율관 배정'!$B:$G,3,FALSE)&"("&VLOOKUP(K40,'자율관 배정'!$B:$F,2,FALSE)&")","") -> () | L41: =IFERROR(VLOOKUP(L40,'자율관 배정'!$B:$G,3,FALSE)&"("&VLOOKUP(L40,'자율관 배정'!$B:$F,2,FALSE)&")","") | M41: =IFERROR(VLOOKUP(M40,'자율관 배정'!$B:$G,3,FALSE)&"("&VLOOKUP(M40,'자율관 배정'!$B:$F,2,FALSE)&")","") -> () | N41: =IFERROR(VLOOKUP(N40,'자율관 배정'!$B:$G,3,FALSE)&"("&VLOOKUP(N40,'자율관 배정'!$B:$F,2,FALSE)&")","") | U41: =IFERROR(VLOOKUP(U40,'자율관 배정'!$B:$G,3,FALSE)&"("&VLOOKUP(U40,'자율관 배정'!$B:$F,2,FALSE)&")","") -> () | V41: =IFERROR(VLOOKUP(V40,'자율관 배정'!$B:$G,3,FALSE)&"("&VLOOKUP(V40,'자율관 배정'!$B:$F,2,FALSE)&")","") | W41: =IFERROR(VLOOKUP(W40,'자율관 배정'!$B:$G,3,FALSE)&"("&VLOOKUP(W40,'자율관 배정'!$B:$F,2,FALSE)&")","") -> () | X41: =IFERROR(VLOOKUP(X40,'자율관 배정'!$B:$G,3,FALSE)&"("&VLOOKUP(X40,'자율관 배정'!$B:$F,2,FALSE)&")","") | Y41: =IFERROR(VLOOKUP(Y40,'자율관 배정'!$B:$G,3,FALSE)&"("&VLOOKUP(Y40,'자율관 배정'!$B:$F,2,FALSE)&")","") -> () | Z41: =IFERROR(VLOOKUP(Z40,'자율관 배정'!$B:$G,3,FALSE)&"("&VLOOKUP(Z40,'자율관 배정'!$B:$F,2,FALSE)&")","") | AB41: =IFERROR(VLOOKUP(AB40,'자율관 배정'!$B:$G,3,FALSE)&"("&VLOOKUP(AB40,'자율관 배정'!$B:$F,2,FALSE)&")","") -> () | AC41: =IFERROR(VLOOKUP(AC40,'자율관 배정'!$B:$G,3,FALSE)&"("&VLOOKUP(AC40,'자율관 배정'!$B:$F,2,FALSE)&")","") | AD41: =IFERROR(VLOOKUP(AD40,'자율관 배정'!$B:$G,3,FALSE)&"("&VLOOKUP(AD40,'자율관 배정'!$B:$F,2,FALSE)&")","") -> () | AE41: =IFERROR(VLOOKUP(AE40,'자율관 배정'!$B:$G,3,FALSE)&"("&VLOOKUP(AE40,'자율관 배정'!$B:$F,2,FALSE)&")","") | AF41: =IFERROR(VLOOKUP(AF40,'자율관 배정'!$B:$G,3,FALSE)&"("&VLOOKUP(AF40,'자율관 배정'!$B:$F,2,FALSE)&")","") -> ()
B42: 2A117 | C42: =IFERROR(VLOOKUP(B42,'자율관 배정'!$B:$G,3,FALSE)&"("&VLOOKUP(B42,'자율관 배정'!$B:$F,2,FALSE)&")","") | E42: 2A023 | F42: 2A022 | G42: 2A021 | I42: 2A020 | J42: 2A019 | K42: 2A018 | L42: 2A017 | M42: 2A016 | N42: 2A015
B43: 2A118 | C43: =IFERROR(VLOOKUP(B43,'자율관 배정'!$B:$G,3,FALSE)&"("&VLOOKUP(B43,'자율관 배정'!$B:$F,2,FALSE)&")","") -> () | E43: =IFERROR(VLOOKUP(E42,'자율관 배정'!$B:$G,3,FALSE)&"("&VLOOKUP(E42,'자율관 배정'!$B:$F,2,FALSE)&")","") -> () | F43: =IFERROR(VLOOKUP(F42,'자율관 배정'!$B:$G,3,FALSE)&"("&VLOOKUP(F42,'자율관 배정'!$B:$F,2,FALSE)&")","") | G43: =IFERROR(VLOOKUP(G42,'자율관 배정'!$B:$G,3,FALSE)&"("&VLOOKUP(G42,'자율관 배정'!$B:$F,2,FALSE)&")","") -> () | I43: =IFERROR(VLOOKUP(I42,'자율관 배정'!$B:$G,3,FALSE)&"("&VLOOKUP(I42,'자율관 배정'!$B:$F,2,FALSE)&")","") | J43: =IFERROR(VLOOKUP(J42,'자율관 배정'!$B:$G,3,FALSE)&"("&VLOOKUP(J42,'자율관 배정'!$B:$F,2,FALSE)&")","") -> () | K43: =IFERROR(VLOOKUP(K42,'자율관 배정'!$B:$G,3,FALSE)&"("&VLOOKUP(K42,'자율관 배정'!$B:$F,2,FALSE)&")","") | L43: =IFERROR(VLOOKUP(L42,'자율관 배정'!$B:$G,3,FALSE)&"("&VLOOKUP(L42,'자율관 배정'!$B:$F,2,FALSE)&")","") -> () | M43: =IFERROR(VLOOKUP(M42,'자율관 배정'!$B:$G,3,FALSE)&"("&VLOOKUP(M42,'자율관 배정'!$B:$F,2,FALSE)&")","") | N43: =IFERROR(VLOOKUP(N42,'자율관 배정'!$B:$G,3,FALSE)&"("&VLOOKUP(N42,'자율관 배정'!$B:$F,2,FALSE)&")","") -> () | U43: 2D036 | V43: 2D035 | W43: 2D034 | X43: 2D033 | Y43: 2D032 | Z43: 2D031 | AB43: 2D030 | AE43: 2D029 | AF43: 2D028
B44: 벽 | U44: =IFERROR(VLOOKUP(U43,'자율관 배정'!$B:$G,3,FALSE)&"("&VLOOKUP(U43,'자율관 배정'!$B:$F,2,FALSE)&")","") | V44: =IFERROR(VLOOKUP(V43,'자율관 배정'!$B:$G,3,FALSE)&"("&VLOOKUP(V43,'자율관 배정'!$B:$F,2,FALSE)&")","") -> () | W44: =IFERROR(VLOOKUP(W43,'자율관 배정'!$B:$G,3,FALSE)&"("&VLOOKUP(W43,'자율관 배정'!$B:$F,2,FALSE)&")","") | X44: =IFERROR(VLOOKUP(X43,'자율관 배정'!$B:$G,3,FALSE)&"("&VLOOKUP(X43,'자율관 배정'!$B:$F,2,FALSE)&")","") -> () | Y44: =IFERROR(VLOOKUP(Y43,'자율관 배정'!$B:$G,3,FALSE)&"("&VLOOKUP(Y43,'자율관 배정'!$B:$F,2,FALSE)&")","") | Z44: =IFERROR(VLOOKUP(Z43,'자율관 배정'!$B:$G,3,FALSE)&"("&VLOOKUP(Z43,'자율관 배정'!$B:$F,2,FALSE)&")","") -> () | AB44: =IFERROR(VLOOKUP(AB43,'자율관 배정'!$B:$G,3,FALSE)&"("&VLOOKUP(AB43,'자율관 배정'!$B:$F,2,FALSE)&")","") | AE44: =IFERROR(VLOOKUP(AE43,'자율관 배정'!$B:$G,3,FALSE)&"("&VLOOKUP(AE43,'자율관 배정'!$B:$F,2,FALSE)&")","") -> () | AF44: =IFERROR(VLOOKUP(AF43,'자율관 배정'!$B:$G,3,FALSE)&"("&VLOOKUP(AF43,'자율관 배정'!$B:$F,2,FALSE)&")","")
B45: 2A119 | C45: =IFERROR(VLOOKUP(B45,'자율관 배정'!$B:$G,3,FALSE)&"("&VLOOKUP(B45,'자율관 배정'!$B:$F,2,FALSE)&")","") -> () | E45: 2A014 | F45: 2A013 | G45: 2A012 | I45: 2A011 | J45: 2A010 | K45: 2A009 | L45: 2A008 | U45: 2D027 | V45: 2D026 | W45: 2D025 | X45: 2D024 | Y45: 2D023 | Z45: 2D022 | AB45: 2D021 | AC45: 2D020 | AD45: 2D019 | AE45: 2D018 | AF45: 2D017
B46: 2A120 | C46: =IFERROR(VLOOKUP(B46,'자율관 배정'!$B:$G,3,FALSE)&"("&VLOOKUP(B46,'자율관 배정'!$B:$F,2,FALSE)&")","") | E46: =IFERROR(VLOOKUP(E45,'자율관 배정'!$B:$G,3,FALSE)&"("&VLOOKUP(E45,'자율관 배정'!$B:$F,2,FALSE)&")","") | F46: =IFERROR(VLOOKUP(F45,'자율관 배정'!$B:$G,3,FALSE)&"("&VLOOKUP(F45,'자율관 배정'!$B:$F,2,FALSE)&")","") -> () | G46: =IFERROR(VLOOKUP(G45,'자율관 배정'!$B:$G,3,FALSE)&"("&VLOOKUP(G45,'자율관 배정'!$B:$F,2,FALSE)&")","") | I46: =IFERROR(VLOOKUP(I45,'자율관 배정'!$B:$G,3,FALSE)&"("&VLOOKUP(I45,'자율관 배정'!$B:$F,2,FALSE)&")","") -> () | J46: =IFERROR(VLOOKUP(J45,'자율관 배정'!$B:$G,3,FALSE)&"("&VLOOKUP(J45,'자율관 배정'!$B:$F,2,FALSE)&")","") | K46: =IFERROR(VLOOKUP(K45,'자율관 배정'!$B:$G,3,FALSE)&"("&VLOOKUP(K45,'자율관 배정'!$B:$F,2,FALSE)&")","") -> () | L46: =IFERROR(VLOOKUP(L45,'자율관 배정'!$B:$G,3,FALSE)&"("&VLOOKUP(L45,'자율관 배정'!$B:$F,2,FALSE)&")","") | T46: 출 입 문 | U46: =IFERROR(VLOOKUP(U45,'자율관 배정'!$B:$G,3,FALSE)&"("&VLOOKUP(U45,'자율관 배정'!$B:$F,2,FALSE)&")","") -> () | V46: =IFERROR(VLOOKUP(V45,'자율관 배정'!$B:$G,3,FALSE)&"("&VLOOKUP(V45,'자율관 배정'!$B:$F,2,FALSE)&")","") | W46: =IFERROR(VLOOKUP(W45,'자율관 배정'!$B:$G,3,FALSE)&"("&VLOOKUP(W45,'자율관 배정'!$B:$F,2,FALSE)&")","") -> () | X46: =IFERROR(VLOOKUP(X45,'자율관 배정'!$B:$G,3,FALSE)&"("&VLOOKUP(X45,'자율관 배정'!$B:$F,2,FALSE)&")","") | Y46: =IFERROR(VLOOKUP(Y45,'자율관 배정'!$B:$G,3,FALSE)&"("&VLOOKUP(Y45,'자율관 배정'!$B:$F,2,FALSE)&")","") -> () | Z46: =IFERROR(VLOOKUP(Z45,'자율관 배정'!$B:$G,3,FALSE)&"("&VLOOKUP(Z45,'자율관 배정'!$B:$F,2,FALSE)&")","") | AB46: =IFERROR(VLOOKUP(AB45,'자율관 배정'!$B:$G,3,FALSE)&"("&VLOOKUP(AB45,'자율관 배정'!$B:$F,2,FALSE)&")","") -> () | AC46: =IFERROR(VLOOKUP(AC45,'자율관 배정'!$B:$G,3,FALSE)&"("&VLOOKUP(AC45,'자율관 배정'!$B:$F,2,FALSE)&")","") | AD46: =IFERROR(VLOOKUP(AD45,'자율관 배정'!$B:$G,3,FALSE)&"("&VLOOKUP(AD45,'자율관 배정'!$B:$F,2,FALSE)&")","") -> () | AE46: =IFERROR(VLOOKUP(AE45,'자율관 배정'!$B:$G,3,FALSE)&"("&VLOOKUP(AE45,'자율관 배정'!$B:$F,2,FALSE)&")","") | AF46: =IFERROR(VLOOKUP(AF45,'자율관 배정'!$B:$G,3,FALSE)&"("&VLOOKUP(AF45,'자율관 배정'!$B:$F,2,FALSE)&")","") -> ()
B47: 2A121 | C47: =IFERROR(VLOOKUP(B47,'자율관 배정'!$B:$G,3,FALSE)&"("&VLOOKUP(B47,'자율관 배정'!$B:$F,2,FALSE)&")","") -> () | E47: 2A007 | F47: 2A006 | G47: 2A005 | I47: 2A004 | J47: 2A003 | K47: 2A002 | L47: 2A001
...

Sheet 자율관 2층
A2: ※ 착석 또는 이석에 체크하고 출결상황을 "O"표시해 주세요. | G2: □착석 / □이석 | L2: 자율관 2층 배치도(2025. 11. 03. ~) | U2: 2025년 월 일 ( )요일 감독교사 (인)
A6: 2B080 | B6: 2B079 | C6: 2B078 | E6: 2B077 | F6: 2B076 | I6: 2B075 | J6: 2B074 | K6: 2B073 | L6: 2B072 | M6: 2B071 | O6: 2B070 | P6: 2B069 | Q6: 2B068 | R6: 2B067 | S6: 2B066 | T6: 2B065 | U6: 2B064 | X6: 2C034 | Y6: 2C033 | Z6: 2C032 | AB6: 2C031 | AC6: 2C030 | AD6: 2C029 | AE6: 2C028 | AF6: 2C027
A7: =IFERROR(VLOOKUP(A6,'자율관 배정 R1'!$B:$F,3,FALSE)&"("&VLOOKUP(A6,'자율관 배정 R1'!$B:$E,2,FALSE)&")","") -> 이유림(1) | B7: =IFERROR(VLOOKUP(B6,'자율관 배정 R1'!$B:$F,3,FALSE)&"("&VLOOKUP(B6,'자율관 배정 R1'!$B:$E,2,FALSE)&")","") -> 장현채(1) | C7: =IFERROR(VLOOKUP(C6,'자율관 배정 R1'!$B:$F,3,FALSE)&"("&VLOOKUP(C6,'자율관 배정 R1'!$B:$E,2,FALSE)&")","") -> 이서현(1) | E7: =IFERROR(VLOOKUP(E6,'자율관 배정 R1'!$B:$F,3,FALSE)&"("&VLOOKUP(E6,'자율관 배정 R1'!$B:$E,2,FALSE)&")","") -> 이다은(1) | F7: =IFERROR(VLOOKUP(F6,'자율관 배정 R1'!$B:$F,3,FALSE)&"("&VLOOKUP(F6,'자율관 배정 R1'!$B:$E,2,FALSE)&")","") -> 양예은(1) | I7: =IFERROR(VLOOKUP(I6,'자율관 배정 R1'!$B:$F,3,FALSE)&"("&VLOOKUP(I6,'자율관 배정 R1'!$B:$E,2,FALSE)&")","") -> 윤서연(1) | J7: =IFERROR(VLOOKUP(J6,'자율관 배정 R1'!$B:$F,3,FALSE)&"("&VLOOKUP(J6,'자율관 배정 R1'!$B:$E,2,FALSE)&")","") -> 신지수(1) | K7: =IFERROR(VLOOKUP(K6,'자율관 배정 R1'!$B:$F,3,FALSE)&"("&VLOOKUP(K6,'자율관 배정 R1'!$B:$E,2,FALSE)&")","") -> 원소윤(1) | L7: =IFERROR(VLOOKUP(L6,'자율관 배정 R1'!$B:$F,3,FALSE)&"("&VLOOKUP(L6,'자율관 배정 R1'!$B:$E,2,FALSE)&")","") -> 신유나(1) | M7: =IFERROR(VLOOKUP(M6,'자율관 배정 R1'!$B:$F,3,FALSE)&"("&VLOOKUP(M6,'자율관 배정 R1'!$B:$E,2,FALSE)&")","") -> 서다나(1) | O7: =IFERROR(VLOOKUP(O6,'자율관 배정 R1'!$B:$F,3,FALSE)&"("&VLOOKUP(O6,'자율관 배정 R1'!$B:$E,2,FALSE)&")","") -> 박연우(1) | P7: =IFERROR(VLOOKUP(P6,'자율관 배정 R1'!$B:$F,3,FALSE)&"("&VLOOKUP(P6,'자율관 배정 R1'!$B:$E,2,FALSE)&")","") -> 박소하(1) | Q7: =IFERROR(VLOOKUP(Q6,'자율관 배정 R1'!$B:$F,3,FALSE)&"("&VLOOKUP(Q6,'자율관 배정 R1'!$B:$E,2,FALSE)&")","") -> 김효린(1) | R7: =IFERROR(VLOOKUP(R6,'자율관 배정 R1'!$B:$F,3,FALSE)&"("&VLOOKUP(R6,'자율관 배정 R1'!$B:$E,2,FALSE)&")","") -> 김령연(1) | S7: =IFERROR(VLOOKUP(S6,'자율관 배정 R1'!$B:$F,3,FALSE)&"("&VLOOKUP(S6,'자율관 배정 R1'!$B:$E,2,FALSE)&")","") -> 김솔(1) | T7: =IFERROR(VLOOKUP(T6,'자율관 배정 R1'!$B:$F,3,FALSE)&"("&VLOOKUP(T6,'자율관 배정 R1'!$B:$E,2,FALSE)&")","") -> 전유담(11) | U7: =IFERROR(VLOOKUP(U6,'자율관 배정 R1'!$B:$F,3,FALSE)&"("&VLOOKUP(U6,'자율관 배정 R1'!$B:$E,2,FALSE)&")","") -> 이하은(11) | X7: =IFERROR(VLOOKUP(X6,'자율관 배정 R1'!$B:$F,3,FALSE)&"("&VLOOKUP(X6,'자율관 배정 R1'!$B:$E,2,FALSE)&")","") -> 조규민(11) | Y7: =IFERROR(VLOOKUP(Y6,'자율관 배정 R1'!$B:$F,3,FALSE)&"("&VLOOKUP(Y6,'자율관 배정 R1'!$B:$E,2,FALSE)&")","") -> 홍석진(10) | Z7: =IFERROR(VLOOKUP(Z6,'자율관 배정 R1'!$B:$F,3,FALSE)&"("&VLOOKUP(Z6,'자율관 배정 R1'!$B:$E,2,FALSE)&")","") -> 나정수(9) | AB7: =IFERROR(VLOOKUP(AB6,'자율관 배정 R1'!$B:$F,3,FALSE)&"("&VLOOKUP(AB6,'자율관 배정 R1'!$B:$E,2,FALSE)&")","") -> 김승하(9) | AC7: =IFERROR(VLOOKUP(AC6,'자율관 배정 R1'!$B:$F,3,FALSE)&"("&VLOOKUP(AC6,'자율관 배정 R1'!$B:$E,2,FALSE)&")","") -> 김승원(8) | AD7: =IFERROR(VLOOKUP(AD6,'자율관 배정 R1'!$B:$F,3,FALSE)&"("&VLOOKUP(AD6,'자율관 배정 R1'!$B:$E,2,FALSE)&")","") -> 김지훈(6) | AE7: =IFERROR(VLOOKUP(AE6,'자율관 배정 R1'!$B:$F,3,FALSE)&"("&VLOOKUP(AE6,'자율관 배정 R1'!$B:$E,2,FALSE)&")","") -> 김우엽(6) | AF7: =IFERROR(VLOOKUP(AF6,'자율관 배정 R1'!$B:$F,3,FALSE)&"("&VLOOKUP(AF6,'자율관 배정 R1'!$B:$E,2,FALSE)&")","") -> 고승혁(6)
A8: =IFERROR(VLOOKUP(A6,'자율관 배정 R1'!$B:$F,5,FALSE)&"","") -> EP면학X | B8: =IFERROR(VLOOKUP(B6,'자율관 배정 R1'!$B:$F,5,FALSE)&"","") -> 월화수목 | C8: =IFERROR(VLOOKUP(C6,'자율관 배정 R1'!$B:$F,5,FALSE)&"","") -> EP면학X | D8: =IFERROR(VLOOKUP(D6,'자율관 배정 R1'!$B:$F,5,FALSE)&"","") | E8: =IFERROR(VLOOKUP(E6,'자율관 배정 R1'!$B:$F,5,FALSE)&"","") -> EP면학X | F8: =IFERROR(VLOOKUP(F6,'자율관 배정 R1'!$B:$F,5,FALSE)&"","") -> EP면학X | I8: =IFERROR(VLOOKUP(I6,'자율관 배정 R1'!$B:$F,5,FALSE)&"","") -> 기숙사 | J8: =IFERROR(VLOOKUP(J6,'자율관 배정 R1'!$B:$F,5,FALSE)&"","") -> EP면학X | K8: =IFERROR(VLOOKUP(K6,'자율관 배정 R1'!$B:$F,5,FALSE)&"","") -> EP면학X | L8: =IFERROR(VLOOKUP(L6,'자율관 배정 R1'!$B:$F,5,FALSE)&"","") -> EP면학X | M8: =IFERROR(VLOOKUP(M6,'자율관 배정 R1'!$B:$F,5,FALSE)&"","") -> 월화수목금 | O8: =IFERROR(VLOOKUP(O6,'자율관 배정 R1'!$B:$F,5,FALSE)&"","") -> 월화수목 | P8: =IFERROR(VLOOKUP(P6,'자율관 배정 R1'!$B:$F,5,FALSE)&"","") -> EP면학X | Q8: =IFERROR(VLOOKUP(Q6,'자율관 배정 R1'!$B:$F,5,FALSE)&"","") -> EP면학X | R8: =IFERROR(VLOOKUP(R6,'자율관 배정 R1'!$B:$F,5,FALSE)&"","") -> 기숙사 | S8: =IFERROR(VLOOKUP(S6,'자율관 배정 R1'!$B:$F,5,FALSE)&"","") -> EP면학X | T8: =IFERROR(VLOOKUP(T6,'자율관 배정 R1'!$B:$F,5,FALSE)&"","") -> EP면학X | U8: =IFERROR(VLOOKUP(U6,'자율관 배정 R1'!$B:$F,5,FALSE)&"","") -> 기숙사 | X8: =IFERROR(VLOOKUP(X6,'자율관 배정 R1'!$B:$F,5,FALSE)&"","") -> 월화수목 | Y8: =IFERROR(VLOOKUP(Y6,'자율관 배정 R1'!$B:$F,5,FALSE)&"","") -> 기숙사 | Z8: =IFERROR(VLOOKUP(Z6,'자율관 배정 R1'!$B:$F,5,FALSE)&"","") -> 기숙사 | AB8: =IFERROR(VLOOKUP(AB6,'자율관 배정 R1'!$B:$F,5,FALSE)&"","") -> 기숙사 | AC8: =IFERROR(VLOOKUP(AC6,'자율관 배정 R1'!$B:$F,5,FALSE)&"","") -> 기숙사 | AD8: =IFERROR(VLOOKUP(AD6,'자율관 배정 R1'!$B:$F,5,FALSE)&"","") -> 기숙사 | AE8: =IFERROR(VLOOKUP(AE6,'자율관 배정 R1'!$B:$F,5,FALSE)&"","") -> 기숙사 | AF8: =IFERROR(VLOOKUP(AF6,'자율관 배정 R1'!$B:$F,5,FALSE)&"","") -> 월화수목
A9: 2B063 | B9: 2B062 | C9: 2B061 | E9: 2B060 | F9: 2B059 | I9: 2B058 | J9: 2B057 | K9: 2B056 | L9: 2B055 | M9: 2B054 | O9: 2B053 | P9: 2B052 | Q9: 2B051 | R9: 2B050 | S9: 2B049 | T9: 2B048 | U9: 2B047 | X9: 2C026 | Y9: 2C025 | Z9: 2C024 | AB9: 2C023 | AC9: 2C022 | AD9: 2C021 | AE9: 2C020 | AF9: 2C019
A10: =IFERROR(VLOOKUP(A9,'자율관 배정 R1'!$B:$F,3,FALSE)&"("&VLOOKUP(A9,'자율관 배정 R1'!$B:$E,2,FALSE)&")","") -> 심비주(2) | B10: =IFERROR(VLOOKUP(B9,'자율관 배정 R1'!$B:$F,3,FALSE)&"("&VLOOKUP(B9,'자율관 배정 R1'!$B:$E,2,FALSE)&")","") -> 박지우(2) | C10: =IFERROR(VLOOKUP(C9,'자율관 배정 R1'!$B:$F,3,FALSE)&"("&VLOOKUP(C9,'자율관 배정 R1'!$B:$E,2,FALSE)&")","") -> 신윤서(2) | E10: =IFERROR(VLOOKUP(E9,'자율관 배정 R1'!$B:$F,3,FALSE)&"("&VLOOKUP(E9,'자율관 배정 R1'!$B:$E,2,FALSE)&")","") -> 남현지(2) | F10: =IFERROR(VLOOKUP(F9,'자율관 배정 R1'!$B:$F,3,FALSE)&"("&VLOOKUP(F9,'자율관 배정 R1'!$B:$E,2,FALSE)&")","") -> 송효주(2) | I10: =IFERROR(VLOOKUP(I9,'자율관 배정 R1'!$B:$F,3,FALSE)&"("&VLOOKUP(I9,'자율관 배정 R1'!$B:$E,2,FALSE)&")","") -> 나윤서(2) | J10: =IFERROR(VLOOKUP(J9,'자율관 배정 R1'!$B:$F,3,FALSE)&"("&VLOOKUP(J9,'자율관 배정 R1'!$B:$E,2,FALSE)&")","") -> 김민선(2) | K10: =IFERROR(VLOOKUP(K9,'자율관 배정 R1'!$B:$F,3,FALSE)&"("&VLOOKUP(K9,'자율관 배정 R1'!$B:$E,2,FALSE)&")","") -> 김수현(2) | L10: =IFERROR(VLOOKUP(L9,'자율관 배정 R1'!$B:$F,3,FALSE)&"("&VLOOKUP(L9,'자율관 배정 R1'!$B:$E,2,FALSE)&")","") -> 최여정(1) | M10: =IFERROR(VLOOKUP(M9,'자율관 배정 R1'!$B:$F,3,FALSE)&"("&VLOOKUP(M9,'자율관 배정 R1'!$B:$E,2,FALSE)&")","") -> 한지효(1) | O10: =IFERROR(VLOOKUP(O9,'자율관 배정 R1'!$B:$F,3,FALSE)&"("&VLOOKUP(O9,'자율관 배정 R1'!$B:$E,2,FALSE)&")","") -> 진나현(1) | P10: =IFERROR(VLOOKUP(P9,'자율관 배정 R1'!$B:$F,3,FALSE)&"("&VLOOKUP(P9,'자율관 배정 R1'!$B:$E,2,FALSE)&")","") -> 정효주(1) | Q10: =IFERROR(VLOOKUP(Q9,'자율관 배정 R1'!$B:$F,3,FALSE)&"("&VLOOKUP(Q9,'자율관 배정 R1'!$B:$E,2,FALSE)&")","") -> 전원희(1) | R10: =IFERROR(VLOOKUP(R9,'자율관 배정 R1'!$B:$F,3,FALSE)&"("&VLOOKUP(R9,'자율관 배정 R1'!$B:$E,2,FALSE)&")","") -> 정유빈(1) | S10: =IFERROR(VLOOKUP(S9,'자율관 배정 R1'!$B:$F,3,FALSE)&"("&VLOOKUP(S9,'자율관 배정 R1'!$B:$E,2,FALSE)&")","") -> 이지윤(1) | T10: =IFERROR(VLOOKUP(T9,'자율관 배정 R1'!$B:$F,3,FALSE)&"("&VLOOKUP(T9,'자율관 배정 R1'!$B:$E,2,FALSE)&")","") -> 박해원(11) | U10: =IFERROR(VLOOKUP(U9,'자율관 배정 R1'!$B:$F,3,FALSE)&"("&VLOOKUP(U9,'자율관 배정 R1'!$B:$E,2,FALSE)&")","") -> 이나엘라(3) | X10: =IFERROR(VLOOKUP(X9,'자율관 배정 R1'!$B:$F,3,FALSE)&"("&VLOOKUP(X9,'자율관 배정 R1'!$B:$E,2,FALSE)&")","") -> 조아훈(5) | Y10: =IFERROR(VLOOKUP(Y9,'자율관 배정 R1'!$B:$F,3,FALSE)&"("&VLOOKUP(Y9,'자율관 배정 R1'!$B:$E,2,FALSE)&")","") -> 김휘연(5) | Z10: =IFERROR(VLOOKUP(Z9,'자율관 배정 R1'!$B:$F,3,FALSE)&"("&VLOOKUP(Z9,'자율관 배정 R1'!$B:$E,2,FALSE)&")","") -> 강병훈(5) | AB10: =IFERROR(VLOOKUP(AB9,'자율관 배정 R1'!$B:$F,3,FALSE)&"("&VLOOKUP(AB9,'자율관 배정 R1'!$B:$E,2,FALSE)&")","") -> 변정빈(4) | AC10: =IFERROR(VLOOKUP(AC9,'자율관 배정 R1'!$B:$F,3,FALSE)&"("&VLOOKUP(AC9,'자율관 배정 R1'!$B:$E,2,FALSE)&")","") -> 박종하(4) | AD10: =IFERROR(VLOOKUP(AD9,'자율관 배정 R1'!$B:$F,3,FALSE)&"("&VLOOKUP(AD9,'자율관 배정 R1'!$B:$E,2,FALSE)&")","") -> 신연운(3) | AE10: =IFERROR(VLOOKUP(AE9,'자율관 배정 R1'!$B:$F,3,FALSE)&"("&VLOOKUP(AE9,'자율관 배정 R1'!$B:$E,2,FALSE)&")","") -> 노현수(3) | AF10: =IFERROR(VLOOKUP(AF9,'자율관 배정 R1'!$B:$F,3,FALSE)&"("&VLOOKUP(AF9,'자율관 배정 R1'!$B:$E,2,FALSE)&")","") -> 김선율(1)
A11: =IFERROR(VLOOKUP(A9,'자율관 배정 R1'!$B:$F,5,FALSE)&"","") -> EP면학X | B11: =IFERROR(VLOOKUP(B9,'자율관 배정 R1'!$B:$F,5,FALSE)&"","") -> 기숙사 | C11: =IFERROR(VLOOKUP(C9,'자율관 배정 R1'!$B:$F,5,FALSE)&"","") -> EP면학X | D11: =IFERROR(VLOOKUP(D9,'자율관 배정 R1'!$B:$F,5,FALSE)&"","") | E11: =IFERROR(VLOOKUP(E9,'자율관 배정 R1'!$B:$F,5,FALSE)&"","") -> 기숙사 | F11: =IFERROR(VLOOKUP(F9,'자율관 배정 R1'!$B:$F,5,FALSE)&"","") -> EP면학X | I11: =IFERROR(VLOOKUP(I9,'자율관 배정 R1'!$B:$F,5,FALSE)&"","") -> 월화수목 | J11: =IFERROR(VLOOKUP(J9,'자율관 배정 R1'!$B:$F,5,FALSE)&"","") -> 월화수목 | K11: =IFERROR(VLOOKUP(K9,'자율관 배정 R1'!$B:$F,5,FALSE)&"","") -> EP면학X | L11: =IFERROR(VLOOKUP(L9,'자율관 배정 R1'!$B:$F,5,FALSE)&"","") -> EP면학X | M11: =IFERROR(VLOOKUP(M9,'자율관 배정 R1'!$B:$F,5,FALSE)&"","") -> 월화수목 | O11: =IFERROR(VLOOKUP(O9,'자율관 배정 R1'!$B:$F,5,FALSE)&"","") -> EP면학X | P11: =IFERROR(VLOOKUP(P9,'자율관 배정 R1'!$B:$F,5,FALSE)&"","") -> 월화수목 | Q11: =IFERROR(VLOOKUP(Q9,'자율관 배정 R1'!$B:$F,5,FALSE)&"","") -> EP면학X | R11: =IFERROR(VLOOKUP(R9,'자율관 배정 R1'!$B:$F,5,FALSE)&"","") -> EP면학X | S11: =IFERROR(VLOOKUP(S9,'자율관 배정 R1'!$B:$F,5,FALSE)&"","") -> EP면학X | T11: =IFERROR(VLOOKUP(T9,'자율관 배정 R1'!$B:$F,5,FALSE)&"","") -> 기숙사 | U11: =IFERROR(VLOOKUP(U9,'자율관 배정 R1'!$B:$F,5,FALSE)&"","") -> EP면학X | X11: =IFERROR(VLOOKUP(X9,'자율관 배정 R1'!$B:$F,5,FALSE)&"","") -> 기숙사 | Y11: =IFERROR(VLOOKUP(Y9,'자율관 배정 R1'!$B:$F,5,FALSE)&"","") -> 기숙사 | Z11: =IFERROR(VLOOKUP(Z9,'자율관 배정 R1'!$B:$F,5,FALSE)&"","") -> 월화수목 | AB11: =IFERROR(VLOOKUP(AB9,'자율관 배정 R1'!$B:$F,5,FALSE)&"","") -> 기숙사 | AC11: =IFERROR(VLOOKUP(AC9,'자율관 배정 R1'!$B:$F,5,FALSE)&"","") -> 기숙사 | AD11: =IFERROR(VLOOKUP(AD9,'자율관 배정 R1'!$B:$F,5,FALSE)&"","") -> 기숙사 | AE11: =IFERROR(VLOOKUP(AE9,'자율관 배정 R1'!$B:$F,5,FALSE)&"","") -> 월화수목 | AF11: =IFERROR(VLOOKUP(AF9,'자율관 배정 R1'!$B:$F,5,FALSE)&"","") -> 기숙사
A13: 2B046 | B13: 2B045 | C13: 2B044 | E13: 2B043 | F13: 2B042 | I13: 2B041 | J13: 2B040 | K13: 2B039 | L13: 2B038 | M13: 2B037 | O13: 2B036 | P13: 2B035 | Q13: 2B034 | R13: 2B033 | S13: 2B032 | T13: 2B031 | U13: 2B030 | X13: 2C018 | Y13: 2C017 | Z13: 2C016 | AB13: 2C015 | AC13: 2C014 | AD13: 2C013 | AE13: 2C012 | AF13: 2C011
A14: =IFERROR(VLOOKUP(A13,'자율관 배정 R1'!$B:$F,3,FALSE)&"("&VLOOKUP(A13,'자율관 배정 R1'!$B:$E,2,FALSE)&")","") -> 오혜빈(3) | B14: =IFERROR(VLOOKUP(B13,'자율관 배정 R1'!$B:$F,3,FALSE)&"("&VLOOKUP(B13,'자율관 배정 R1'!$B:$E,2,FALSE)&")","") -> 권민성(3) | C14: =IFERROR(VLOOKUP(C13,'자율관 배정 R1'!$B:$F,3,FALSE)&"("&VLOOKUP(C13,'자율관 배정 R1'!$B:$E,2,FALSE)&")","") -> 문서영(3) | E14: =IFERROR(VLOOKUP(E13,'자율관 배정 R1'!$B:$F,3,FALSE)&"("&VLOOKUP(E13,'자율관 배정 R1'!$B:$E,2,FALSE)&")","") -> 허윤지(2) | F14: =IFERROR(VLOOKUP(F13,'자율관 배정 R1'!$B:$F,3,FALSE)&"("&VLOOKUP(F13,'자율관 배정 R1'!$B:$E,2,FALSE)&")","") -> 김유안(3) | I14: =IFERROR(VLOOKUP(I13,'자율관 배정 R1'!$B:$F,3,FALSE)&"("&VLOOKUP(I13,'자율관 배정 R1'!$B:$E,2,FALSE)&")","") -> 한지우(2) | J14: =IFERROR(VLOOKUP(J13,'자율관 배정 R1'!$B:$F,3,FALSE)&"("&VLOOKUP(J13,'자율관 배정 R1'!$B:$E,2,FALSE)&")","") -> 김유리(3) | K14: =IFERROR(VLOOKUP(K13,'자율관 배정 R1'!$B:$F,3,FALSE)&"("&VLOOKUP(K13,'자율관 배정 R1'!$B:$E,2,FALSE)&")","") -> 이은(2) | L14: =IFERROR(VLOOKUP(L13,'자율관 배정 R1'!$B:$F,3,FALSE)&"("&VLOOKUP(L13,'자율관 배정 R1'!$B:$E,2,FALSE)&")","") -> 한예현(2) | M14: =IFERROR(VLOOKUP(M13,'자율관 배정 R1'!$B:$F,3,FALSE)&"("&VLOOKUP(M13,'자율관 배정 R1'!$B:$E,2,FALSE)&")","") -> 이서빈(2) | O14: =IFERROR(VLOOKUP(O13,'자율관 배정 R1'!$B:$F,3,FALSE)&"("&VLOOKUP(O13,'자율관 배정 R1'!$B:$E,2,FALSE)&")","") -> 최예빈(2) | P14: =IFERROR(VLOOKUP(P13,'자율관 배정 R1'!$B:$F,3,FALSE)&"("&VLOOKUP(P13,'자율관 배정 R1'!$B:$E,2,FALSE)&")","") -> 이나연(2) | Q14: =IFERROR(VLOOKUP(Q13,'자율관 배정 R1'!$B:$F,3,FALSE)&"("&VLOOKUP(Q13,'자율관 배정 R1'!$B:$E,2,FALSE)&")","") -> 유지원(2) | R14: =IFERROR(VLOOKUP(R13,'자율관 배정 R1'!$B:$F,3,FALSE)&"("&VLOOKUP(R13,'자율관 배정 R1'!$B:$E,2,FALSE)&")","") -> 박혜은(2) | S14: =IFERROR(VLOOKUP(S13,'자율관 배정 R1'!$B:$F,3,FALSE)&"("&VLOOKUP(S13,'자율관 배정 R1'!$B:$E,2,FALSE)&")","") -> 안수인(2) | T14: =IFERROR(VLOOKUP(T13,'자율관 배정 R1'!$B:$F,3,FALSE)&"("&VLOOKUP(T13,'자율관 배정 R1'!$B:$E,2,FALSE)&")","") -> 한지민(10) | U14: =IFERROR(VLOOKUP(U13,'자율관 배정 R1'!$B:$F,3,FALSE)&"("&VLOOKUP(U13,'자율관 배정 R1'!$B:$E,2,FALSE)&")","") -> 이현(4) | X14: =IFERROR(VLOOKUP(X13,'자율관 배정 R1'!$B:$F,3,FALSE)&"("&VLOOKUP(X13,'자율관 배정 R1'!$B:$E,2,FALSE)&")","") -> 이지수(9) | Y14: =IFERROR(VLOOKUP(Y13,'자율관 배정 R1'!$B:$F,3,FALSE)&"("&VLOOKUP(Y13,'자율관 배정 R1'!$B:$E,2,FALSE)&")","") -> 이선영(9) | Z14: =IFERROR(VLOOKUP(Z13,'자율관 배정 R1'!$B:$F,3,FALSE)&"("&VLOOKUP(Z13,'자율관 배정 R1'!$B:$E,2,FALSE)&")","") -> 이수진(9) | AB14: =IFERROR(VLOOKUP(AB13,'자율관 배정 R1'!$B:$F,3,FALSE)&"("&VLOOKUP(AB13,'자율관 배정 R1'!$B:$E,2,FALSE)&")","") -> 지수민(8) | AC14: =IFERROR(VLOOKUP(AC13,'자율관 배정 R1'!$B:$F,3,FALSE)&"("&VLOOKUP(AC13,'자율관 배정 R1'!$B:$E,2,FALSE)&")","") -> 전성주(7) | AD14: =IFERROR(VLOOKUP(AD13,'자율관 배정 R1'!$B:$F,3,FALSE)&"("&VLOOKUP(AD13,'자율관 배정 R1'!$B:$E,2,FALSE)&")","") -> 박민영(7) | AE14: =IFERROR(VLOOKUP(AE13,'자율관 배정 R1'!$B:$F,3,FALSE)&"("&VLOOKUP(AE13,'자율관 배정 R1'!$B:$E,2,FALSE)&")","") -> () | AF14: =IFERROR(VLOOKUP(AF13,'자율관 배정 R1'!$B:$F,3,FALSE)&"("&VLOOKUP(AF13,'자율관 배정 R1'!$B:$E,2,FALSE)&")","") -> 조효인(4)
A15: =IFERROR(VLOOKUP(A13,'자율관 배정 R1'!$B:$F,5,FALSE)&"","") -> EP면학X | B15: =IFERROR(VLOOKUP(B13,'자율관 배정 R1'!$B:$F,5,FALSE)&"","") -> EP면학X | C15: =IFERROR(VLOOKUP(C13,'자율관 배정 R1'!$B:$F,5,FALSE)&"","") -> EP면학X | D15: =IFERROR(VLOOKUP(D13,'자율관 배정 R1'!$B:$F,5,FALSE)&"","") | E15: =IFERROR(VLOOKUP(E13,'자율관 배정 R1'!$B:$F,5,FALSE)&"","") -> 기숙사 | F15: =IFERROR(VLOOKUP(F13,'자율관 배정 R1'!$B:$F,5,FALSE)&"","") -> EP면학X | I15: =IFERROR(VLOOKUP(I13,'자율관 배정 R1'!$B:$F,5,FALSE)&"","") -> 월화수목 | J15: =IFERROR(VLOOKUP(J13,'자율관 배정 R1'!$B:$F,5,FALSE)&"","") -> EP면학X | K15: =IFERROR(VLOOKUP(K13,'자율관 배정 R1'!$B:$F,5,FALSE)&"","") -> 기숙사 | L15: =IFERROR(VLOOKUP(L13,'자율관 배정 R1'!$B:$F,5,FALSE)&"","") -> EP면학X | M15: =IFERROR(VLOOKUP(M13,'자율관 배정 R1'!$B:$F,5,FALSE)&"","") -> EP면학X | O15: =IFERROR(VLOOKUP(O13,'자율관 배정 R1'!$B:$F,5,FALSE)&"","") -> EP면학X | P15: =IFERROR(VLOOKUP(P13,'자율관 배정 R1'!$B:$F,5,FALSE)&"","") -> EP면학X | Q15: =IFERROR(VLOOKUP(Q13,'자율관 배정 R1'!$B:$F,5,FALSE)&"","") -> EP면학X | R15: =IFERROR(VLOOKUP(R13,'자율관 배정 R1'!$B:$F,5,FALSE)&"","") -> 기숙사 | S15: =IFERROR(VLOOKUP(S13,'자율관 배정 R1'!$B:$F,5,FALSE)&"","") -> EP면학X | T15: =IFERROR(VLOOKUP(T13,'자율관 배정 R1'!$B:$F,5,FALSE)&"","") -> 기숙사 | U15: =IFERROR(VLOOKUP(U13,'자율관 배정 R1'!$B:$F,5,FALSE)&"","") -> EP면학X | X15: =IFERROR(VLOOKUP(X13,'자율관 배정 R1'!$B:$F,5,FALSE)&"","") -> 월화수목 | Y15: =IFERROR(VLOOKUP(Y13,'자율관 배정 R1'!$B:$F,5,FALSE)&"","") -> 기숙사 | Z15: =IFERROR(VLOOKUP(Z13,'자율관 배정 R1'!$B:$F,5,FALSE)&"","") -> 월화수목 | AB15: =IFERROR(VLOOKUP(AB13,'자율관 배정 R1'!$B:$F,5,FALSE)&"","") -> 기숙사 | AC15: =IFERROR(VLOOKUP(AC13,'자율관 배정 R1'!$B:$F,5,FALSE)&"","") -> 기숙사 | AD15: =IFERROR(VLOOKUP(AD13,'자율관 배정 R1'!$B:$F,5,FALSE)&"","") -> 기숙사 | AE15: =IFERROR(VLOOKUP(AE13,'자율관 배정 R1'!$B:$F,5,FALSE)&"","") | AF15: =IFERROR(VLOOKUP(AF13,'자율관 배정 R1'!$B:$F,5,FALSE)&"","") -> 기숙사
A16: 2B029 | B16: 2B028 | C16: 2B027 | E16: 2B026 | F16: 2B025 | I16: 2B024 | J16: 2B023 | K16: 2B022 | L16: 2B021 | M16: 2B020 | O16: 2B019 | P16: 2B018 | Q16: 2B017 | R16: 2B016 | S16: 2B015 | T16: 2B014 | U16: 2B013 | X16: 2C010 | Y16: 2C009 | Z16: 2C008 | AB16: 2C007 | AC16: 2C006 | AD16: 2C005 | AE16: 2C004 | AF16: 2C003
A17: =IFERROR(VLOOKUP(A16,'자율관 배정 R1'!$B:$F,3,FALSE)&"("&VLOOKUP(A16,'자율관 배정 R1'!$B:$E,2,FALSE)&")","") -> 임소은(4) | B17: =IFERROR(VLOOKUP(B16,'자율관 배정 R1'!$B:$F,3,FALSE)&"("&VLOOKUP(B16,'자율관 배정 R1'!$B:$E,2,FALSE)&")","") -> 전아정(3) | C17: =IFERROR(VLOOKUP(C16,'자율관 배정 R1'!$B:$F,3,FALSE)&"("&VLOOKUP(C16,'자율관 배정 R1'!$B:$E,2,FALSE)&")","") -> 이지효(4) | E17: =IFERROR(VLOOKUP(E16,'자율관 배정 R1'!$B:$F,3,FALSE)&"("&VLOOKUP(E16,'자율관 배정 R1'!$B:$E,2,FALSE)&")","") -> 장영우(3) | F17: =IFERROR(VLOOKUP(F16,'자율관 배정 R1'!$B:$F,3,FALSE)&"("&VLOOKUP(F16,'자율관 배정 R1'!$B:$E,2,FALSE)&")","") -> 이다연(4) | I17: =IFERROR(VLOOKUP(I16,'자율관 배정 R1'!$B:$F,3,FALSE)&"("&VLOOKUP(I16,'자율관 배정 R1'!$B:$E,2,FALSE)&")","") -> 이민선(3) | J17: =IFERROR(VLOOKUP(J16,'자율관 배정 R1'!$B:$F,3,FALSE)&"("&VLOOKUP(J16,'자율관 배정 R1'!$B:$E,2,FALSE)&")","") -> 엄수영(4) | K17: =IFERROR(VLOOKUP(K16,'자율관 배정 R1'!$B:$F,3,FALSE)&"("&VLOOKUP(K16,'자율관 배정 R1'!$B:$E,2,FALSE)&")","") -> 이나경(3) | L17: =IFERROR(VLOOKUP(L16,'자율관 배정 R1'!$B:$F,3,FALSE)&"("&VLOOKUP(L16,'자율관 배정 R1'!$B:$E,2,FALSE)&")","") -> 박선영(4) | M17: =IFERROR(VLOOKUP(M16,'자율관 배정 R1'!$B:$F,3,FALSE)&"("&VLOOKUP(M16,'자율관 배정 R1'!$B:$E,2,FALSE)&")","") -> 유초열(3) | O17: =IFERROR(VLOOKUP(O16,'자율관 배정 R1'!$B:$F,3,FALSE)&"("&VLOOKUP(O16,'자율관 배정 R1'!$B:$E,2,FALSE)&")","") -> 남효정(4) | P17: =IFERROR(VLOOKUP(P16,'자율관 배정 R1'!$B:$F,3,FALSE)&"("&VLOOKUP(P16,'자율관 배정 R1'!$B:$E,2,FALSE)&")","") -> 남지윤(3) | Q17: =IFERROR(VLOOKUP(Q16,'자율관 배정 R1'!$B:$F,3,FALSE)&"("&VLOOKUP(Q16,'자율관 배정 R1'!$B:$E,2,FALSE)&")","") -> 한초윤(3) | R17: =IFERROR(VLOOKUP(R16,'자율관 배정 R1'!$B:$F,3,FALSE)&"("&VLOOKUP(R16,'자율관 배정 R1'!$B:$E,2,FALSE)&")","") -> 김나현(3) | S17: =IFERROR(VLOOKUP(S16,'자율관 배정 R1'!$B:$F,3,FALSE)&"("&VLOOKUP(S16,'자율관 배정 R1'!$B:$E,2,FALSE)&")","") -> 장연주(3) | T17: =IFERROR(VLOOKUP(T16,'자율관 배정 R1'!$B:$F,3,FALSE)&"("&VLOOKUP(T16,'자율관 배정 R1'!$B:$E,2,FALSE)&")","") -> 이재영(10) | U17: =IFERROR(VLOOKUP(U16,'자율관 배정 R1'!$B:$F,3,FALSE)&"("&VLOOKUP(U16,'자율관 배정 R1'!$B:$E,2,FALSE)&")","") -> 조하늬(9) | X17: =IFERROR(VLOOKUP(X16,'자율관 배정 R1'!$B:$F,3,FALSE)&"("&VLOOKUP(X16,'자율관 배정 R1'!$B:$E,2,FALSE)&")","") -> 강지윤(4) | Y17: =IFERROR(VLOOKUP(Y16,'자율관 배정 R1'!$B:$F,3,FALSE)&"("&VLOOKUP(Y16,'자율관 배정 R1'!$B:$E,2,FALSE)&")","") -> 강서현(11) | Z17: =IFERROR(VLOOKUP(Z16,'자율관 배정 R1'!$B:$F,3,FALSE)&"("&VLOOKUP(Z16,'자율관 배정 R1'!$B:$E,2,FALSE)&")","") -> () | AB17: =IFERROR(VLOOKUP(AB16,'자율관 배정 R1'!$B:$F,3,FALSE)&"("&VLOOKUP(AB16,'자율관 배정 R1'!$B:$E,2,FALSE)&")","") -> 연예은(3) | AC17: =IFERROR(VLOOKUP(AC16,'자율관 배정 R1'!$B:$F,3,FALSE)&"("&VLOOKUP(AC16,'자율관 배정 R1'!$B:$E,2,FALSE)&")","") -> 이서현(3) | AD17: =IFERROR(VLOOKUP(AD16,'자율관 배정 R1'!$B:$F,3,FALSE)&"("&VLOOKUP(AD16,'자율관 배정 R1'!$B:$E,2,FALSE)&")","") -> 김서영(3) | AE17: =IFERROR(VLOOKUP(AE16,'자율관 배정 R1'!$B:$F,3,FALSE)&"("&VLOOKUP(AE16,'자율관 배정 R1'!$B:$E,2,FALSE)&")","") -> 조하은(2) | AF17: =IFERROR(VLOOKUP(AF16,'자율관 배정 R1'!$B:$F,3,FALSE)&"("&VLOOKUP(AF16,'자율관 배정 R1'!$B:$E,2,FALSE)&")","") -> 석지원(2)
A18: =IFERROR(VLOOKUP(A16,'자율관 배정 R1'!$B:$F,5,FALSE)&"","") -> EP면학X | B18: =IFERROR(VLOOKUP(B16,'자율관 배정 R1'!$B:$F,5,FALSE)&"","") -> EP면학X | C18: =IFERROR(VLOOKUP(C16,'자율관 배정 R1'!$B:$F,5,FALSE)&"","") -> EP면학X | D18: =IFERROR(VLOOKUP(D16,'자율관 배정 R1'!$B:$F,5,FALSE)&"","") | E18: =IFERROR(VLOOKUP(E16,'자율관 배정 R1'!$B:$F,5,FALSE)&"","") -> 월화수목 | F18: =IFERROR(VLOOKUP(F16,'자율관 배정 R1'!$B:$F,5,FALSE)&"","") -> EP면학X | I18: =IFERROR(VLOOKUP(I16,'자율관 배정 R1'!$B:$F,5,FALSE)&"","") -> 기숙사 | J18: =IFERROR(VLOOKUP(J16,'자율관 배정 R1'!$B:$F,5,FALSE)&"","") -> EP면학X | K18: =IFERROR(VLOOKUP(K16,'자율관 배정 R1'!$B:$F,5,FALSE)&"","") -> 기숙사 | L18: =IFERROR(VLOOKUP(L16,'자율관 배정 R1'!$B:$F,5,FALSE)&"","") -> EP면학X | M18: =IFERROR(VLOOKUP(M16,'자율관 배정 R1'!$B:$F,5,FALSE)&"","") -> 기숙사 | O18: =IFERROR(VLOOKUP(O16,'자율관 배정 R1'!$B:$F,5,FALSE)&"","") -> EP면학X | P18: =IFERROR(VLOOKUP(P16,'자율관 배정 R1'!$B:$F,5,FALSE)&"","") -> 기숙사 | Q18: =IFERROR(VLOOKUP(Q16,'자율관 배정 R1'!$B:$F,5,FALSE)&"","") -> EP면학X | R18: =IFERROR(VLOOKUP(R16,'자율관 배정 R1'!$B:$F,5,FALSE)&"","") -> 월화수목 | S18: =IFERROR(VLOOKUP(S16,'자율관 배정 R1'!$B:$F,5,FALSE)&"","") -> EP면학X | T18: =IFERROR(VLOOKUP(T16,'자율관 배정 R1'!$B:$F,5,FALSE)&"","") -> EP면학X | U18: =IFERROR(VLOOKUP(U16,'자율관 배정 R1'!$B:$F,5,FALSE)&"","") -> 월목 | X18: =IFERROR(VLOOKUP(X16,'자율관 배정 R1'!$B:$F,5,FALSE)&"","") -> 월화수목 | Y18: =IFERROR(VLOOKUP(Y16,'자율관 배정 R1'!$B:$F,5,FALSE)&"","") -> 월화수목금 | Z18: =IFERROR(VLOOKUP(Z16,'자율관 배정 R1'!$B:$F,5,FALSE)&"","") | AB18: =IFERROR(VLOOKUP(AB16,'자율관 배정 R1'!$B:$F,5,FALSE)&"","") -> 월화수목금 | AC18: =IFERROR(VLOOKUP(AC16,'자율관 배정 R1'!$B:$F,5,FALSE)&"","") -> 기숙사 | AD18: =IFERROR(VLOOKUP(AD16,'자율관 배정 R1'!$B:$F,5,FALSE)&"","") -> EP면학X | AE18: =IFERROR(VLOOKUP(AE16,'자율관 배정 R1'!$B:$F,5,FALSE)&"","") -> 기숙사 | AF18: =IFERROR(VLOOKUP(AF16,'자율관 배정 R1'!$B:$F,5,FALSE)&"","") -> EP면학X
A20: 2B012 | B20: 2B011 | C20: 2B010 | E20: 2B009 | F20: 2B008 | J20: 2B007 | K20: 2B006 | L20: 2B005 | M20: 2B004 | T20: 2B003 | U20: 2B002 | V20: 2B001 | AE20: 2C002 | AF20: 2C001
